<mujoco model="humanoid">
  <compiler coordinate="local"/>
  <default>
    <joint damping="0.0" armature="0.01" stiffness="0.0" limited="true"/>
    <geom conaffinity="1" condim="3" contype="7" margin="0.001" rgba="0.8 0.6 .4 1"/>
  </default>
  <asset>
    <texture type="skybox" builtin="gradient" rgb1=".4 .5 .6" rgb2="0 0 0" width="100" height="100"/>
    <texture builtin="flat" height="1278" mark="cross" markrgb="1 1 1" name="texgeom" random="0.01" rgb1="0.8 0.6 0.4" rgb2="0.8 0.6 0.4" type="cube" width="127"/>
    <texture builtin="checker" height="100" name="texplane" rgb1="0 0 0" rgb2="0.8 0.8 0.8" type="2d" width="100"/>
    <material name="MatPlane" reflectance="0.5" shininess="1" specular="1" texrepeat="60 60" texture="texplane"/>
    <material name="geom" texture="texgeom" texuniform="true"/>
    <mesh file="d4eca668-a453-49f7-a04a-a3d326538694/geom/Pelvis.stl" name="Pelvis_mesh"/>
    <mesh file="d4eca668-a453-49f7-a04a-a3d326538694/geom/L_Hip.stl" name="L_Hip_mesh"/>
    <mesh file="d4eca668-a453-49f7-a04a-a3d326538694/geom/R_Hip.stl" name="R_Hip_mesh"/>
    <mesh file="d4eca668-a453-49f7-a04a-a3d326538694/geom/Torso.stl" name="Torso_mesh"/>
    <mesh file="d4eca668-a453-49f7-a04a-a3d326538694/geom/L_Knee.stl" name="L_Knee_mesh"/>
    <mesh file="d4eca668-a453-49f7-a04a-a3d326538694/geom/R_Knee.stl" name="R_Knee_mesh"/>
    <mesh file="d4eca668-a453-49f7-a04a-a3d326538694/geom/Spine.stl" name="Spine_mesh"/>
    <mesh file="d4eca668-a453-49f7-a04a-a3d326538694/geom/L_Ankle.stl" name="L_Ankle_mesh"/>
    <mesh file="d4eca668-a453-49f7-a04a-a3d326538694/geom/R_Ankle.stl" name="R_Ankle_mesh"/>
    <mesh file="d4eca668-a453-49f7-a04a-a3d326538694/geom/Chest.stl" name="Chest_mesh"/>
    <mesh file="d4eca668-a453-49f7-a04a-a3d326538694/geom/L_Toe.stl" name="L_Toe_mesh"/>
    <mesh file="d4eca668-a453-49f7-a04a-a3d326538694/geom/R_Toe.stl" name="R_Toe_mesh"/>
    <mesh file="d4eca668-a453-49f7-a04a-a3d326538694/geom/Neck.stl" name="Neck_mesh"/>
    <mesh file="d4eca668-a453-49f7-a04a-a3d326538694/geom/L_Thorax.stl" name="L_Thorax_mesh"/>
    <mesh file="d4eca668-a453-49f7-a04a-a3d326538694/geom/R_Thorax.stl" name="R_Thorax_mesh"/>
    <mesh file="d4eca668-a453-49f7-a04a-a3d326538694/geom/Head.stl" name="Head_mesh"/>
    <mesh file="d4eca668-a453-49f7-a04a-a3d326538694/geom/L_Shoulder.stl" name="L_Shoulder_mesh"/>
    <mesh file="d4eca668-a453-49f7-a04a-a3d326538694/geom/R_Shoulder.stl" name="R_Shoulder_mesh"/>
    <mesh file="d4eca668-a453-49f7-a04a-a3d326538694/geom/L_Elbow.stl" name="L_Elbow_mesh"/>
    <mesh file="d4eca668-a453-49f7-a04a-a3d326538694/geom/R_Elbow.stl" name="R_Elbow_mesh"/>
    <mesh file="d4eca668-a453-49f7-a04a-a3d326538694/geom/L_Wrist.stl" name="L_Wrist_mesh"/>
    <mesh file="d4eca668-a453-49f7-a04a-a3d326538694/geom/R_Wrist.stl" name="R_Wrist_mesh"/>
    <mesh file="d4eca668-a453-49f7-a04a-a3d326538694/geom/L_Index1.stl" name="L_Index1_mesh"/>
    <mesh file="d4eca668-a453-49f7-a04a-a3d326538694/geom/L_Index2.stl" name="L_Index2_mesh"/>
    <mesh file="d4eca668-a453-49f7-a04a-a3d326538694/geom/L_Index3.stl" name="L_Index3_mesh"/>
    <mesh file="d4eca668-a453-49f7-a04a-a3d326538694/geom/L_Middle1.stl" name="L_Middle1_mesh"/>
    <mesh file="d4eca668-a453-49f7-a04a-a3d326538694/geom/L_Middle2.stl" name="L_Middle2_mesh"/>
    <mesh file="d4eca668-a453-49f7-a04a-a3d326538694/geom/L_Middle3.stl" name="L_Middle3_mesh"/>
    <mesh file="d4eca668-a453-49f7-a04a-a3d326538694/geom/L_Pinky1.stl" name="L_Pinky1_mesh"/>
    <mesh file="d4eca668-a453-49f7-a04a-a3d326538694/geom/L_Pinky2.stl" name="L_Pinky2_mesh"/>
    <mesh file="d4eca668-a453-49f7-a04a-a3d326538694/geom/L_Pinky3.stl" name="L_Pinky3_mesh"/>
    <mesh file="d4eca668-a453-49f7-a04a-a3d326538694/geom/L_Ring1.stl" name="L_Ring1_mesh"/>
    <mesh file="d4eca668-a453-49f7-a04a-a3d326538694/geom/L_Ring2.stl" name="L_Ring2_mesh"/>
    <mesh file="d4eca668-a453-49f7-a04a-a3d326538694/geom/L_Ring3.stl" name="L_Ring3_mesh"/>
    <mesh file="d4eca668-a453-49f7-a04a-a3d326538694/geom/L_Thumb1.stl" name="L_Thumb1_mesh"/>
    <mesh file="d4eca668-a453-49f7-a04a-a3d326538694/geom/L_Thumb2.stl" name="L_Thumb2_mesh"/>
    <mesh file="d4eca668-a453-49f7-a04a-a3d326538694/geom/L_Thumb3.stl" name="L_Thumb3_mesh"/>
    <mesh file="d4eca668-a453-49f7-a04a-a3d326538694/geom/R_Index1.stl" name="R_Index1_mesh"/>
    <mesh file="d4eca668-a453-49f7-a04a-a3d326538694/geom/R_Index2.stl" name="R_Index2_mesh"/>
    <mesh file="d4eca668-a453-49f7-a04a-a3d326538694/geom/R_Index3.stl" name="R_Index3_mesh"/>
    <mesh file="d4eca668-a453-49f7-a04a-a3d326538694/geom/R_Middle1.stl" name="R_Middle1_mesh"/>
    <mesh file="d4eca668-a453-49f7-a04a-a3d326538694/geom/R_Middle2.stl" name="R_Middle2_mesh"/>
    <mesh file="d4eca668-a453-49f7-a04a-a3d326538694/geom/R_Middle3.stl" name="R_Middle3_mesh"/>
    <mesh file="d4eca668-a453-49f7-a04a-a3d326538694/geom/R_Pinky1.stl" name="R_Pinky1_mesh"/>
    <mesh file="d4eca668-a453-49f7-a04a-a3d326538694/geom/R_Pinky2.stl" name="R_Pinky2_mesh"/>
    <mesh file="d4eca668-a453-49f7-a04a-a3d326538694/geom/R_Pinky3.stl" name="R_Pinky3_mesh"/>
    <mesh file="d4eca668-a453-49f7-a04a-a3d326538694/geom/R_Ring1.stl" name="R_Ring1_mesh"/>
    <mesh file="d4eca668-a453-49f7-a04a-a3d326538694/geom/R_Ring2.stl" name="R_Ring2_mesh"/>
    <mesh file="d4eca668-a453-49f7-a04a-a3d326538694/geom/R_Ring3.stl" name="R_Ring3_mesh"/>
    <mesh file="d4eca668-a453-49f7-a04a-a3d326538694/geom/R_Thumb1.stl" name="R_Thumb1_mesh"/>
    <mesh file="d4eca668-a453-49f7-a04a-a3d326538694/geom/R_Thumb2.stl" name="R_Thumb2_mesh"/>
    <mesh file="d4eca668-a453-49f7-a04a-a3d326538694/geom/R_Thumb3.stl" name="R_Thumb3_mesh"/>
  </asset>
  <worldbody>
    <light cutoff="100" diffuse="1 1 1" dir="-0 0 -1.3" directional="true" exponent="1" pos="0 0 1.3" specular=".1 .1 .1"/>
    <geom conaffinity="1" condim="3" name="floor" pos="0 0 0" rgba="0.8 0.9 0.8 1" size="100 100 .2" type="plane" material="MatPlane"/>
    <body name="Pelvis" pos="-0.0001 -0.2499 0.0254">
      <freejoint name="Pelvis"/>
      <geom type="mesh" mesh="Pelvis_mesh" density="500" contype="1" conaffinity="1"/>
      <body name="L_Hip" pos="-0.0211 0.0632 -0.0856">
        <joint name="L_Hip_z" type="hinge" pos="0 0 0" axis="0 0 1" user="800 80 1 500" armature="0.01" range="-180.0000 180.0000" damping="0" stiffness="0"/>
        <joint name="L_Hip_y" type="hinge" pos="0 0 0" axis="0 1 0" user="800 80 1 500" armature="0.01" range="-180.0000 180.0000" damping="0" stiffness="0"/>
        <joint name="L_Hip_x" type="hinge" pos="0 0 0" axis="1 0 0" user="800 80 1 500" armature="0.01" range="-180.0000 180.0000" damping="0" stiffness="0"/>
        <geom type="mesh" mesh="L_Hip_mesh" density="500" contype="1" conaffinity="1"/>
        <body name="L_Knee" pos="0.0051 0.0415 -0.384">
          <joint name="L_Knee_z" type="hinge" pos="0 0 0" axis="0 0 1" user="800 80 1 500" armature="0.01" range="-180.0000 180.0000" damping="0" stiffness="0"/>
          <joint name="L_Knee_y" type="hinge" pos="0 0 0" axis="0 1 0" user="800 80 1 500" armature="0.01" range="-180.0000 180.0000" damping="0" stiffness="0"/>
          <joint name="L_Knee_x" type="hinge" pos="0 0 0" axis="1 0 0" user="800 80 1 500" armature="0.01" range="-180.0000 180.0000" damping="0" stiffness="0"/>
          <geom type="mesh" mesh="L_Knee_mesh" density="500" contype="1" conaffinity="1"/>
          <body name="L_Ankle" pos="-0.0397 -0.0153 -0.421">
            <joint name="L_Ankle_z" type="hinge" pos="0 0 0" axis="0 0 1" user="800 80 1 500" armature="0.01" range="-180.0000 180.0000" damping="0" stiffness="0"/>
            <joint name="L_Ankle_y" type="hinge" pos="0 0 0" axis="0 1 0" user="800 80 1 500" armature="0.01" range="-180.0000 180.0000" damping="0" stiffness="0"/>
            <joint name="L_Ankle_x" type="hinge" pos="0 0 0" axis="1 0 0" user="800 80 1 500" armature="0.01" range="-180.0000 180.0000" damping="0" stiffness="0"/>
            <geom density="230.639339" type="box" pos="0.0220 0.0271 -0.0244" size="0.0918 0.0529 0.0495" quat="1.0000 0.0000 0.0000 0.0000"/>
            <body name="L_Toe" pos="0.1253 0.0398 -0.0609">
              <joint name="L_Toe_z" type="hinge" pos="0 0 0" axis="0 0 1" user="500 50 1 500" armature="0.01" range="-180.0000 180.0000" damping="0" stiffness="0"/>
              <joint name="L_Toe_y" type="hinge" pos="0 0 0" axis="0 1 0" user="500 50 1 500" armature="0.01" range="-180.0000 180.0000" damping="0" stiffness="0"/>
              <joint name="L_Toe_x" type="hinge" pos="0 0 0" axis="1 0 0" user="500 50 1 500" armature="0.01" range="-180.0000 180.0000" damping="0" stiffness="0"/>
              <geom density="212.501146" type="box" pos="0.0268 -0.0127 0.0094" size="0.0534 0.0518 0.0224" quat="1.0000 0.0000 0.0000 0.0000"/>
            </body>
          </body>
        </body>
      </body>
      <body name="R_Hip" pos="-0.0171 -0.0651 -0.0933">
        <joint name="R_Hip_z" type="hinge" pos="0 0 0" axis="0 0 1" user="800 80 1 500" armature="0.01" range="-180.0000 180.0000" damping="0" stiffness="0"/>
        <joint name="R_Hip_y" type="hinge" pos="0 0 0" axis="0 1 0" user="800 80 1 500" armature="0.01" range="-180.0000 180.0000" damping="0" stiffness="0"/>
        <joint name="R_Hip_x" type="hinge" pos="0 0 0" axis="1 0 0" user="800 80 1 500" armature="0.01" range="-180.0000 180.0000" damping="0" stiffness="0"/>
        <geom type="mesh" mesh="R_Hip_mesh" density="500" contype="1" conaffinity="1"/>
        <body name="R_Knee" pos="-0.0074 -0.0427 -0.3839">
          <joint name="R_Knee_z" type="hinge" pos="0 0 0" axis="0 0 1" user="800 80 1 500" armature="0.01" range="-180.0000 180.0000" damping="0" stiffness="0"/>
          <joint name="R_Knee_y" type="hinge" pos="0 0 0" axis="0 1 0" user="800 80 1 500" armature="0.01" range="-180.0000 180.0000" damping="0" stiffness="0"/>
          <joint name="R_Knee_x" type="hinge" pos="0 0 0" axis="1 0 0" user="800 80 1 500" armature="0.01" range="-180.0000 180.0000" damping="0" stiffness="0"/>
          <geom type="mesh" mesh="R_Knee_mesh" density="500" contype="1" conaffinity="1"/>
          <body name="R_Ankle" pos="-0.0366 0.0198 -0.4158">
            <joint name="R_Ankle_z" type="hinge" pos="0 0 0" axis="0 0 1" user="800 80 1 500" armature="0.01" range="-180.0000 180.0000" damping="0" stiffness="0"/>
            <joint name="R_Ankle_y" type="hinge" pos="0 0 0" axis="0 1 0" user="800 80 1 500" armature="0.01" range="-180.0000 180.0000" damping="0" stiffness="0"/>
            <joint name="R_Ankle_x" type="hinge" pos="0 0 0" axis="1 0 0" user="800 80 1 500" armature="0.01" range="-180.0000 180.0000" damping="0" stiffness="0"/>
            <geom density="222.200982" type="box" pos="0.0256 -0.0316 -0.0278" size="0.0932 0.0545 0.0513" quat="1.0000 0.0000 0.0000 0.0000"/>
            <body name="R_Toe" pos="0.1339 -0.0372 -0.0626">
              <joint name="R_Toe_z" type="hinge" pos="0 0 0" axis="0 0 1" user="500 50 1 500" armature="0.01" range="-180.0000 180.0000" damping="0" stiffness="0"/>
              <joint name="R_Toe_y" type="hinge" pos="0 0 0" axis="0 1 0" user="500 50 1 500" armature="0.01" range="-180.0000 180.0000" damping="0" stiffness="0"/>
              <joint name="R_Toe_x" type="hinge" pos="0 0 0" axis="1 0 0" user="500 50 1 500" armature="0.01" range="-180.0000 180.0000" damping="0" stiffness="0"/>
              <geom density="221.478448" type="box" pos="0.0205 0.0056 0.0071" size="0.0525 0.0533 0.0235" quat="1.0000 0.0000 0.0000 0.0000"/>
            </body>
          </body>
        </body>
      </body>
      <body name="Torso" pos="-0.036 0.0042 0.1275">
        <joint name="Torso_z" type="hinge" pos="0 0 0" axis="0 0 1" user="1000 100 1 500" armature="0.01" range="-180.0000 180.0000" damping="0" stiffness="0"/>
        <joint name="Torso_y" type="hinge" pos="0 0 0" axis="0 1 0" user="1000 100 1 500" armature="0.01" range="-180.0000 180.0000" damping="0" stiffness="0"/>
        <joint name="Torso_x" type="hinge" pos="0 0 0" axis="1 0 0" user="1000 100 1 500" armature="0.01" range="-180.0000 180.0000" damping="0" stiffness="0"/>
        <geom type="mesh" mesh="Torso_mesh" density="500" contype="1" conaffinity="1"/>
        <body name="Spine" pos="0.0306 0.0035 0.1409">
          <joint name="Spine_z" type="hinge" pos="0 0 0" axis="0 0 1" user="1000 100 1 500" armature="0.01" range="-180.0000 180.0000" damping="0" stiffness="0"/>
          <joint name="Spine_y" type="hinge" pos="0 0 0" axis="0 1 0" user="1000 100 1 500" armature="0.01" range="-180.0000 180.0000" damping="0" stiffness="0"/>
          <joint name="Spine_x" type="hinge" pos="0 0 0" axis="1 0 0" user="1000 100 1 500" armature="0.01" range="-180.0000 180.0000" damping="0" stiffness="0"/>
          <geom type="mesh" mesh="Spine_mesh" density="500" contype="1" conaffinity="1"/>
          <body name="Chest" pos="0.0063 -0.0027 0.057">
            <joint name="Chest_z" type="hinge" pos="0 0 0" axis="0 0 1" user="1000 100 1 500" armature="0.01" range="-180.0000 180.0000" damping="0" stiffness="0"/>
            <joint name="Chest_y" type="hinge" pos="0 0 0" axis="0 1 0" user="1000 100 1 500" armature="0.01" range="-180.0000 180.0000" damping="0" stiffness="0"/>
            <joint name="Chest_x" type="hinge" pos="0 0 0" axis="1 0 0" user="1000 100 1 500" armature="0.01" range="-180.0000 180.0000" damping="0" stiffness="0"/>
            <geom type="mesh" mesh="Chest_mesh" density="500" contype="1" conaffinity="1"/>
            <body name="Neck" pos="-0.0411 -0.0142 0.2194">
              <joint name="Neck_z" type="hinge" pos="0 0 0" axis="0 0 1" user="500 50 1 250" armature="0.01" range="-180.0000 180.0000" damping="0" stiffness="0"/>
              <joint name="Neck_y" type="hinge" pos="0 0 0" axis="0 1 0" user="500 50 1 250" armature="0.01" range="-180.0000 180.0000" damping="0" stiffness="0"/>
              <joint name="Neck_x" type="hinge" pos="0 0 0" axis="1 0 0" user="500 50 1 250" armature="0.01" range="-180.0000 180.0000" damping="0" stiffness="0"/>
              <geom type="mesh" mesh="Neck_mesh" density="500" contype="1" conaffinity="1"/>
              <body name="Head" pos="0.0528 0.01 0.0873">
                <joint name="Head_z" type="hinge" pos="0 0 0" axis="0 0 1" user="500 50 1 250" armature="0.01" range="-180.0000 180.0000" damping="0" stiffness="0"/>
                <joint name="Head_y" type="hinge" pos="0 0 0" axis="0 1 0" user="500 50 1 250" armature="0.01" range="-180.0000 180.0000" damping="0" stiffness="0"/>
                <joint name="Head_x" type="hinge" pos="0 0 0" axis="1 0 0" user="500 50 1 250" armature="0.01" range="-180.0000 180.0000" damping="0" stiffness="0"/>
                <geom type="mesh" mesh="Head_mesh" density="500" contype="1" conaffinity="1"/>
              </body>
            </body>
            <body name="L_Thorax" pos="-0.0234 0.0731 0.1181">
              <joint name="L_Thorax_z" type="hinge" pos="0 0 0" axis="0 0 1" user="500 50 1 500" armature="0.01" range="-180.0000 180.0000" damping="0" stiffness="0"/>
              <joint name="L_Thorax_y" type="hinge" pos="0 0 0" axis="0 1 0" user="500 50 1 500" armature="0.01" range="-180.0000 180.0000" damping="0" stiffness="0"/>
              <joint name="L_Thorax_x" type="hinge" pos="0 0 0" axis="1 0 0" user="500 50 1 500" armature="0.01" range="-180.0000 180.0000" damping="0" stiffness="0"/>
              <geom type="mesh" mesh="L_Thorax_mesh" density="500" contype="1" conaffinity="1"/>
              <body name="L_Shoulder" pos="-0.0194 0.1266 0.0451">
                <joint name="L_Shoulder_z" type="hinge" pos="0 0 0" axis="0 0 1" user="500 50 1 500" armature="0.01" range="-180.0000 180.0000" damping="0" stiffness="0"/>
                <joint name="L_Shoulder_y" type="hinge" pos="0 0 0" axis="0 1 0" user="500 50 1 500" armature="0.01" range="-180.0000 180.0000" damping="0" stiffness="0"/>
                <joint name="L_Shoulder_x" type="hinge" pos="0 0 0" axis="1 0 0" user="500 50 1 500" armature="0.01" range="-180.0000 180.0000" damping="0" stiffness="0"/>
                <geom type="mesh" mesh="L_Shoulder_mesh" density="500" contype="1" conaffinity="1"/>
                <body name="L_Elbow" pos="-0.0219 0.2557 -0.0144">
                  <joint name="L_Elbow_z" type="hinge" pos="0 0 0" axis="0 0 1" user="500 50 1 150" armature="0.01" range="-720.0000 720.0000" damping="0" stiffness="0"/>
                  <joint name="L_Elbow_y" type="hinge" pos="0 0 0" axis="0 1 0" user="500 50 1 150" armature="0.01" range="-720.0000 720.0000" damping="0" stiffness="0"/>
                  <joint name="L_Elbow_x" type="hinge" pos="0 0 0" axis="1 0 0" user="500 50 1 150" armature="0.01" range="-720.0000 720.0000" damping="0" stiffness="0"/>
                  <geom type="mesh" mesh="L_Elbow_mesh" density="500" contype="1" conaffinity="1"/>
                  <body name="L_Wrist" pos="-0.0057 0.2615 0.0125">
                    <joint name="L_Wrist_z" type="hinge" pos="0 0 0" axis="0 0 1" user="300 30 1 150" armature="0.01" range="-180.0000 180.0000" damping="0" stiffness="0"/>
                    <joint name="L_Wrist_y" type="hinge" pos="0 0 0" axis="0 1 0" user="300 30 1 150" armature="0.01" range="-180.0000 180.0000" damping="0" stiffness="0"/>
                    <joint name="L_Wrist_x" type="hinge" pos="0 0 0" axis="1 0 0" user="300 30 1 150" armature="0.01" range="-180.0000 180.0000" damping="0" stiffness="0"/>
                    <geom type="mesh" mesh="L_Wrist_mesh" density="500" contype="1" conaffinity="1"/>
                    <body name="L_Index1" pos="0.0229 0.108 -0.0114">
                      <joint name="L_Index1_z" type="hinge" pos="0 0 0" axis="0 0 1" user="100 10 1 150" armature="0.01" range="-180.0000 180.0000" damping="0" stiffness="0"/>
                      <joint name="L_Index1_y" type="hinge" pos="0 0 0" axis="0 1 0" user="100 10 1 150" armature="0.01" range="-180.0000 180.0000" damping="0" stiffness="0"/>
                      <joint name="L_Index1_x" type="hinge" pos="0 0 0" axis="1 0 0" user="100 10 1 150" armature="0.01" range="-180.0000 180.0000" damping="0" stiffness="0"/>
                      <geom type="mesh" mesh="L_Index1_mesh" density="500" contype="1" conaffinity="1"/>
                      <body name="L_Index2" pos="0.0019 0.0317 -0.0124">
                        <joint name="L_Index2_z" type="hinge" pos="0 0 0" axis="0 0 1" user="100 10 1 150" armature="0.01" range="-180.0000 180.0000" damping="0" stiffness="0"/>
                        <joint name="L_Index2_y" type="hinge" pos="0 0 0" axis="0 1 0" user="100 10 1 150" armature="0.01" range="-180.0000 180.0000" damping="0" stiffness="0"/>
                        <joint name="L_Index2_x" type="hinge" pos="0 0 0" axis="1 0 0" user="100 10 1 150" armature="0.01" range="-180.0000 180.0000" damping="0" stiffness="0"/>
                        <geom type="mesh" mesh="L_Index2_mesh" density="500" contype="1" conaffinity="1"/>
                        <body name="L_Index3" pos="-0.0019 0.0064 -0.023">
                          <joint name="L_Index3_z" type="hinge" pos="0 0 0" axis="0 0 1" user="100 10 1 150" armature="0.01" range="-180.0000 180.0000" damping="0" stiffness="0"/>
                          <joint name="L_Index3_y" type="hinge" pos="0 0 0" axis="0 1 0" user="100 10 1 150" armature="0.01" range="-180.0000 180.0000" damping="0" stiffness="0"/>
                          <joint name="L_Index3_x" type="hinge" pos="0 0 0" axis="1 0 0" user="100 10 1 150" armature="0.01" range="-180.0000 180.0000" damping="0" stiffness="0"/>
                          <geom type="mesh" mesh="L_Index3_mesh" density="500" contype="1" conaffinity="1"/>
                        </body>
                      </body>
                    </body>
                    <body name="L_Middle1" pos="-0.0019 0.1162 -0.0082">
                      <joint name="L_Middle1_z" type="hinge" pos="0 0 0" axis="0 0 1" user="100 10 1 150" armature="0.01" range="-180.0000 180.0000" damping="0" stiffness="0"/>
                      <joint name="L_Middle1_y" type="hinge" pos="0 0 0" axis="0 1 0" user="100 10 1 150" armature="0.01" range="-180.0000 180.0000" damping="0" stiffness="0"/>
                      <joint name="L_Middle1_x" type="hinge" pos="0 0 0" axis="1 0 0" user="100 10 1 150" armature="0.01" range="-180.0000 180.0000" damping="0" stiffness="0"/>
                      <geom type="mesh" mesh="L_Middle1_mesh" density="500" contype="1" conaffinity="1"/>
                      <body name="L_Middle2" pos="-0.0044 0.0281 -0.0166">
                        <joint name="L_Middle2_z" type="hinge" pos="0 0 0" axis="0 0 1" user="100 10 1 150" armature="0.01" range="-180.0000 180.0000" damping="0" stiffness="0"/>
                        <joint name="L_Middle2_y" type="hinge" pos="0 0 0" axis="0 1 0" user="100 10 1 150" armature="0.01" range="-180.0000 180.0000" damping="0" stiffness="0"/>
                        <joint name="L_Middle2_x" type="hinge" pos="0 0 0" axis="1 0 0" user="100 10 1 150" armature="0.01" range="-180.0000 180.0000" damping="0" stiffness="0"/>
                        <geom type="mesh" mesh="L_Middle2_mesh" density="500" contype="1" conaffinity="1"/>
                        <body name="L_Middle3" pos="-0.001 0.0053 -0.0248">
                          <joint name="L_Middle3_z" type="hinge" pos="0 0 0" axis="0 0 1" user="100 10 1 150" armature="0.01" range="-180.0000 180.0000" damping="0" stiffness="0"/>
                          <joint name="L_Middle3_y" type="hinge" pos="0 0 0" axis="0 1 0" user="100 10 1 150" armature="0.01" range="-180.0000 180.0000" damping="0" stiffness="0"/>
                          <joint name="L_Middle3_x" type="hinge" pos="0 0 0" axis="1 0 0" user="100 10 1 150" armature="0.01" range="-180.0000 180.0000" damping="0" stiffness="0"/>
                          <geom type="mesh" mesh="L_Middle3_mesh" density="500" contype="1" conaffinity="1"/>
                        </body>
                      </body>
                    </body>
                    <body name="L_Pinky1" pos="-0.0455 0.0896 -0.0153">
                      <joint name="L_Pinky1_z" type="hinge" pos="0 0 0" axis="0 0 1" user="100 10 1 150" armature="0.01" range="-180.0000 180.0000" damping="0" stiffness="0"/>
                      <joint name="L_Pinky1_y" type="hinge" pos="0 0 0" axis="0 1 0" user="100 10 1 150" armature="0.01" range="-180.0000 180.0000" damping="0" stiffness="0"/>
                      <joint name="L_Pinky1_x" type="hinge" pos="0 0 0" axis="1 0 0" user="100 10 1 150" armature="0.01" range="-180.0000 180.0000" damping="0" stiffness="0"/>
                      <geom type="mesh" mesh="L_Pinky1_mesh" density="500" contype="1" conaffinity="1"/>
                      <body name="L_Pinky2" pos="-0.0044 0.0144 -0.0147">
                        <joint name="L_Pinky2_z" type="hinge" pos="0 0 0" axis="0 0 1" user="100 10 1 150" armature="0.01" range="-180.0000 180.0000" damping="0" stiffness="0"/>
                        <joint name="L_Pinky2_y" type="hinge" pos="0 0 0" axis="0 1 0" user="100 10 1 150" armature="0.01" range="-180.0000 180.0000" damping="0" stiffness="0"/>
                        <joint name="L_Pinky2_x" type="hinge" pos="0 0 0" axis="1 0 0" user="100 10 1 150" armature="0.01" range="-180.0000 180.0000" damping="0" stiffness="0"/>
                        <geom type="mesh" mesh="L_Pinky2_mesh" density="500" contype="1" conaffinity="1"/>
                        <body name="L_Pinky3" pos="0.0018 0.0048 -0.0197">
                          <joint name="L_Pinky3_z" type="hinge" pos="0 0 0" axis="0 0 1" user="100 10 1 150" armature="0.01" range="-180.0000 180.0000" damping="0" stiffness="0"/>
                          <joint name="L_Pinky3_y" type="hinge" pos="0 0 0" axis="0 1 0" user="100 10 1 150" armature="0.01" range="-180.0000 180.0000" damping="0" stiffness="0"/>
                          <joint name="L_Pinky3_x" type="hinge" pos="0 0 0" axis="1 0 0" user="100 10 1 150" armature="0.01" range="-180.0000 180.0000" damping="0" stiffness="0"/>
                          <geom type="mesh" mesh="L_Pinky3_mesh" density="500" contype="1" conaffinity="1"/>
                        </body>
                      </body>
                    </body>
                    <body name="L_Ring1" pos="-0.0272 0.1036 -0.0103">
                      <joint name="L_Ring1_z" type="hinge" pos="0 0 0" axis="0 0 1" user="100 10 1 150" armature="0.01" range="-180.0000 180.0000" damping="0" stiffness="0"/>
                      <joint name="L_Ring1_y" type="hinge" pos="0 0 0" axis="0 1 0" user="100 10 1 150" armature="0.01" range="-180.0000 180.0000" damping="0" stiffness="0"/>
                      <joint name="L_Ring1_x" type="hinge" pos="0 0 0" axis="1 0 0" user="100 10 1 150" armature="0.01" range="-180.0000 180.0000" damping="0" stiffness="0"/>
                      <geom type="mesh" mesh="L_Ring1_mesh" density="500" contype="1" conaffinity="1"/>
                      <body name="L_Ring2" pos="-0.0001 0.025 -0.0175">
                        <joint name="L_Ring2_z" type="hinge" pos="0 0 0" axis="0 0 1" user="100 10 1 150" armature="0.01" range="-180.0000 180.0000" damping="0" stiffness="0"/>
                        <joint name="L_Ring2_y" type="hinge" pos="0 0 0" axis="0 1 0" user="100 10 1 150" armature="0.01" range="-180.0000 180.0000" damping="0" stiffness="0"/>
                        <joint name="L_Ring2_x" type="hinge" pos="0 0 0" axis="1 0 0" user="100 10 1 150" armature="0.01" range="-180.0000 180.0000" damping="0" stiffness="0"/>
                        <geom type="mesh" mesh="L_Ring2_mesh" density="500" contype="1" conaffinity="1"/>
                        <body name="L_Ring3" pos="0.0023 0.0043 -0.0248">
                          <joint name="L_Ring3_z" type="hinge" pos="0 0 0" axis="0 0 1" user="100 10 1 150" armature="0.01" range="-180.0000 180.0000" damping="0" stiffness="0"/>
                          <joint name="L_Ring3_y" type="hinge" pos="0 0 0" axis="0 1 0" user="100 10 1 150" armature="0.01" range="-180.0000 180.0000" damping="0" stiffness="0"/>
                          <joint name="L_Ring3_x" type="hinge" pos="0 0 0" axis="1 0 0" user="100 10 1 150" armature="0.01" range="-180.0000 180.0000" damping="0" stiffness="0"/>
                          <geom type="mesh" mesh="L_Ring3_mesh" density="500" contype="1" conaffinity="1"/>
                        </body>
                      </body>
                    </body>
                    <body name="L_Thumb1" pos="0.03 0.043 -0.0239">
                      <joint name="L_Thumb1_z" type="hinge" pos="0 0 0" axis="0 0 1" user="100 10 1 150" armature="0.01" range="-180.0000 180.0000" damping="0" stiffness="0"/>
                      <joint name="L_Thumb1_y" type="hinge" pos="0 0 0" axis="0 1 0" user="100 10 1 150" armature="0.01" range="-180.0000 180.0000" damping="0" stiffness="0"/>
                      <joint name="L_Thumb1_x" type="hinge" pos="0 0 0" axis="1 0 0" user="100 10 1 150" armature="0.01" range="-180.0000 180.0000" damping="0" stiffness="0"/>
                      <geom type="mesh" mesh="L_Thumb1_mesh" density="500" contype="1" conaffinity="1"/>
                      <body name="L_Thumb2" pos="0.0139 0.0241 -0.0172">
                        <joint name="L_Thumb2_z" type="hinge" pos="0 0 0" axis="0 0 1" user="100 10 1 150" armature="0.01" range="-180.0000 180.0000" damping="0" stiffness="0"/>
                        <joint name="L_Thumb2_y" type="hinge" pos="0 0 0" axis="0 1 0" user="100 10 1 150" armature="0.01" range="-180.0000 180.0000" damping="0" stiffness="0"/>
                        <joint name="L_Thumb2_x" type="hinge" pos="0 0 0" axis="1 0 0" user="100 10 1 150" armature="0.01" range="-180.0000 180.0000" damping="0" stiffness="0"/>
                        <geom type="mesh" mesh="L_Thumb2_mesh" density="500" contype="1" conaffinity="1"/>
                        <body name="L_Thumb3" pos="0.0074 0.0264 -0.006">
                          <joint name="L_Thumb3_z" type="hinge" pos="0 0 0" axis="0 0 1" user="100 10 1 150" armature="0.01" range="-180.0000 180.0000" damping="0" stiffness="0"/>
                          <joint name="L_Thumb3_y" type="hinge" pos="0 0 0" axis="0 1 0" user="100 10 1 150" armature="0.01" range="-180.0000 180.0000" damping="0" stiffness="0"/>
                          <joint name="L_Thumb3_x" type="hinge" pos="0 0 0" axis="1 0 0" user="100 10 1 150" armature="0.01" range="-180.0000 180.0000" damping="0" stiffness="0"/>
                          <geom type="mesh" mesh="L_Thumb3_mesh" density="500" contype="1" conaffinity="1"/>
                        </body>
                      </body>
                    </body>
                  </body>
                </body>
              </body>
            </body>
            <body name="R_Thorax" pos="-0.0287 -0.0859 0.1171">
              <joint name="R_Thorax_z" type="hinge" pos="0 0 0" axis="0 0 1" user="500 50 1 150" armature="0.01" range="-180.0000 180.0000" damping="0" stiffness="0"/>
              <joint name="R_Thorax_y" type="hinge" pos="0 0 0" axis="0 1 0" user="500 50 1 150" armature="0.01" range="-180.0000 180.0000" damping="0" stiffness="0"/>
              <joint name="R_Thorax_x" type="hinge" pos="0 0 0" axis="1 0 0" user="500 50 1 150" armature="0.01" range="-180.0000 180.0000" damping="0" stiffness="0"/>
              <geom type="mesh" mesh="R_Thorax_mesh" density="500" contype="1" conaffinity="1"/>
              <body name="R_Shoulder" pos="-0.0073 -0.1168 0.0481">
                <joint name="R_Shoulder_z" type="hinge" pos="0 0 0" axis="0 0 1" user="500 50 1 250" armature="0.01" range="-180.0000 180.0000" damping="0" stiffness="0"/>
                <joint name="R_Shoulder_y" type="hinge" pos="0 0 0" axis="0 1 0" user="500 50 1 250" armature="0.01" range="-180.0000 180.0000" damping="0" stiffness="0"/>
                <joint name="R_Shoulder_x" type="hinge" pos="0 0 0" axis="1 0 0" user="500 50 1 250" armature="0.01" range="-180.0000 180.0000" damping="0" stiffness="0"/>
                <geom type="mesh" mesh="R_Shoulder_mesh" density="500" contype="1" conaffinity="1"/>
                <body name="R_Elbow" pos="-0.032 -0.26 -0.0129">
                  <joint name="R_Elbow_z" type="hinge" pos="0 0 0" axis="0 0 1" user="500 50 1 150" armature="0.01" range="-720.0000 720.0000" damping="0" stiffness="0"/>
                  <joint name="R_Elbow_y" type="hinge" pos="0 0 0" axis="0 1 0" user="500 50 1 150" armature="0.01" range="-720.0000 720.0000" damping="0" stiffness="0"/>
                  <joint name="R_Elbow_x" type="hinge" pos="0 0 0" axis="1 0 0" user="500 50 1 150" armature="0.01" range="-720.0000 720.0000" damping="0" stiffness="0"/>
                  <geom type="mesh" mesh="R_Elbow_mesh" density="500" contype="1" conaffinity="1"/>
                  <body name="R_Wrist" pos="-0.0048 -0.2659 0.0048">
                    <joint name="R_Wrist_z" type="hinge" pos="0 0 0" axis="0 0 1" user="300 30 1 150" armature="0.01" range="-180.0000 180.0000" damping="0" stiffness="0"/>
                    <joint name="R_Wrist_y" type="hinge" pos="0 0 0" axis="0 1 0" user="300 30 1 150" armature="0.01" range="-180.0000 180.0000" damping="0" stiffness="0"/>
                    <joint name="R_Wrist_x" type="hinge" pos="0 0 0" axis="1 0 0" user="300 30 1 150" armature="0.01" range="-180.0000 180.0000" damping="0" stiffness="0"/>
                    <geom type="mesh" mesh="R_Wrist_mesh" density="500" contype="1" conaffinity="1"/>
                    <body name="R_Index1" pos="0.0278 -0.1072 -0.0091">
                      <joint name="R_Index1_z" type="hinge" pos="0 0 0" axis="0 0 1" user="100 10 1 150" armature="0.01" range="-180.0000 180.0000" damping="0" stiffness="0"/>
                      <joint name="R_Index1_y" type="hinge" pos="0 0 0" axis="0 1 0" user="100 10 1 150" armature="0.01" range="-180.0000 180.0000" damping="0" stiffness="0"/>
                      <joint name="R_Index1_x" type="hinge" pos="0 0 0" axis="1 0 0" user="100 10 1 150" armature="0.01" range="-180.0000 180.0000" damping="0" stiffness="0"/>
                      <geom type="mesh" mesh="R_Index1_mesh" density="500" contype="1" conaffinity="1"/>
                      <body name="R_Index2" pos="0.0006 -0.0329 -0.0117">
                        <joint name="R_Index2_z" type="hinge" pos="0 0 0" axis="0 0 1" user="100 10 1 150" armature="0.01" range="-180.0000 180.0000" damping="0" stiffness="0"/>
                        <joint name="R_Index2_y" type="hinge" pos="0 0 0" axis="0 1 0" user="100 10 1 150" armature="0.01" range="-180.0000 180.0000" damping="0" stiffness="0"/>
                        <joint name="R_Index2_x" type="hinge" pos="0 0 0" axis="1 0 0" user="100 10 1 150" armature="0.01" range="-180.0000 180.0000" damping="0" stiffness="0"/>
                        <geom type="mesh" mesh="R_Index2_mesh" density="500" contype="1" conaffinity="1"/>
                        <body name="R_Index3" pos="-0.0032 -0.0071 -0.0229">
                          <joint name="R_Index3_z" type="hinge" pos="0 0 0" axis="0 0 1" user="100 10 1 150" armature="0.01" range="-180.0000 180.0000" damping="0" stiffness="0"/>
                          <joint name="R_Index3_y" type="hinge" pos="0 0 0" axis="0 1 0" user="100 10 1 150" armature="0.01" range="-180.0000 180.0000" damping="0" stiffness="0"/>
                          <joint name="R_Index3_x" type="hinge" pos="0 0 0" axis="1 0 0" user="100 10 1 150" armature="0.01" range="-180.0000 180.0000" damping="0" stiffness="0"/>
                          <geom type="mesh" mesh="R_Index3_mesh" density="500" contype="1" conaffinity="1"/>
                        </body>
                      </body>
                    </body>
                    <body name="R_Middle1" pos="0.0014 -0.1162 -0.0051">
                      <joint name="R_Middle1_z" type="hinge" pos="0 0 0" axis="0 0 1" user="100 10 1 150" armature="0.01" range="-180.0000 180.0000" damping="0" stiffness="0"/>
                      <joint name="R_Middle1_y" type="hinge" pos="0 0 0" axis="0 1 0" user="100 10 1 150" armature="0.01" range="-180.0000 180.0000" damping="0" stiffness="0"/>
                      <joint name="R_Middle1_x" type="hinge" pos="0 0 0" axis="1 0 0" user="100 10 1 150" armature="0.01" range="-180.0000 180.0000" damping="0" stiffness="0"/>
                      <geom type="mesh" mesh="R_Middle1_mesh" density="500" contype="1" conaffinity="1"/>
                      <body name="R_Middle2" pos="-0.0048 -0.0288 -0.0157">
                        <joint name="R_Middle2_z" type="hinge" pos="0 0 0" axis="0 0 1" user="100 10 1 150" armature="0.01" range="-180.0000 180.0000" damping="0" stiffness="0"/>
                        <joint name="R_Middle2_y" type="hinge" pos="0 0 0" axis="0 1 0" user="100 10 1 150" armature="0.01" range="-180.0000 180.0000" damping="0" stiffness="0"/>
                        <joint name="R_Middle2_x" type="hinge" pos="0 0 0" axis="1 0 0" user="100 10 1 150" armature="0.01" range="-180.0000 180.0000" damping="0" stiffness="0"/>
                        <geom type="mesh" mesh="R_Middle2_mesh" density="500" contype="1" conaffinity="1"/>
                        <body name="R_Middle3" pos="-0.0016 -0.0056 -0.0246">
                          <joint name="R_Middle3_z" type="hinge" pos="0 0 0" axis="0 0 1" user="100 10 1 150" armature="0.01" range="-180.0000 180.0000" damping="0" stiffness="0"/>
                          <joint name="R_Middle3_y" type="hinge" pos="0 0 0" axis="0 1 0" user="100 10 1 150" armature="0.01" range="-180.0000 180.0000" damping="0" stiffness="0"/>
                          <joint name="R_Middle3_x" type="hinge" pos="0 0 0" axis="1 0 0" user="100 10 1 150" armature="0.01" range="-180.0000 180.0000" damping="0" stiffness="0"/>
                          <geom type="mesh" mesh="R_Middle3_mesh" density="500" contype="1" conaffinity="1"/>
                        </body>
                      </body>
                    </body>
                    <body name="R_Pinky1" pos="-0.0437 -0.0906 -0.0139">
                      <joint name="R_Pinky1_z" type="hinge" pos="0 0 0" axis="0 0 1" user="100 10 1 150" armature="0.01" range="-180.0000 180.0000" damping="0" stiffness="0"/>
                      <joint name="R_Pinky1_y" type="hinge" pos="0 0 0" axis="0 1 0" user="100 10 1 150" armature="0.01" range="-180.0000 180.0000" damping="0" stiffness="0"/>
                      <joint name="R_Pinky1_x" type="hinge" pos="0 0 0" axis="1 0 0" user="100 10 1 150" armature="0.01" range="-180.0000 180.0000" damping="0" stiffness="0"/>
                      <geom type="mesh" mesh="R_Pinky1_mesh" density="500" contype="1" conaffinity="1"/>
                      <body name="R_Pinky2" pos="-0.0047 -0.0139 -0.015">
                        <joint name="R_Pinky2_z" type="hinge" pos="0 0 0" axis="0 0 1" user="100 10 1 150" armature="0.01" range="-180.0000 180.0000" damping="0" stiffness="0"/>
                        <joint name="R_Pinky2_y" type="hinge" pos="0 0 0" axis="0 1 0" user="100 10 1 150" armature="0.01" range="-180.0000 180.0000" damping="0" stiffness="0"/>
                        <joint name="R_Pinky2_x" type="hinge" pos="0 0 0" axis="1 0 0" user="100 10 1 150" armature="0.01" range="-180.0000 180.0000" damping="0" stiffness="0"/>
                        <geom type="mesh" mesh="R_Pinky2_mesh" density="500" contype="1" conaffinity="1"/>
                        <body name="R_Pinky3" pos="0.0015 -0.0046 -0.0197">
                          <joint name="R_Pinky3_z" type="hinge" pos="0 0 0" axis="0 0 1" user="100 10 1 150" armature="0.01" range="-180.0000 180.0000" damping="0" stiffness="0"/>
                          <joint name="R_Pinky3_y" type="hinge" pos="0 0 0" axis="0 1 0" user="100 10 1 150" armature="0.01" range="-180.0000 180.0000" damping="0" stiffness="0"/>
                          <joint name="R_Pinky3_x" type="hinge" pos="0 0 0" axis="1 0 0" user="100 10 1 150" armature="0.01" range="-180.0000 180.0000" damping="0" stiffness="0"/>
                          <geom type="mesh" mesh="R_Pinky3_mesh" density="500" contype="1" conaffinity="1"/>
                        </body>
                      </body>
                    </body>
                    <body name="R_Ring1" pos="-0.0252 -0.1042 -0.0077">
                      <joint name="R_Ring1_z" type="hinge" pos="0 0 0" axis="0 0 1" user="100 10 1 150" armature="0.01" range="-180.0000 180.0000" damping="0" stiffness="0"/>
                      <joint name="R_Ring1_y" type="hinge" pos="0 0 0" axis="0 1 0" user="100 10 1 150" armature="0.01" range="-180.0000 180.0000" damping="0" stiffness="0"/>
                      <joint name="R_Ring1_x" type="hinge" pos="0 0 0" axis="1 0 0" user="100 10 1 150" armature="0.01" range="-180.0000 180.0000" damping="0" stiffness="0"/>
                      <geom type="mesh" mesh="R_Ring1_mesh" density="500" contype="1" conaffinity="1"/>
                      <body name="R_Ring2" pos="-0.0012 -0.0255 -0.0167">
                        <joint name="R_Ring2_z" type="hinge" pos="0 0 0" axis="0 0 1" user="100 10 1 150" armature="0.01" range="-180.0000 180.0000" damping="0" stiffness="0"/>
                        <joint name="R_Ring2_y" type="hinge" pos="0 0 0" axis="0 1 0" user="100 10 1 150" armature="0.01" range="-180.0000 180.0000" damping="0" stiffness="0"/>
                        <joint name="R_Ring2_x" type="hinge" pos="0 0 0" axis="1 0 0" user="100 10 1 150" armature="0.01" range="-180.0000 180.0000" damping="0" stiffness="0"/>
                        <geom type="mesh" mesh="R_Ring2_mesh" density="500" contype="1" conaffinity="1"/>
                        <body name="R_Ring3" pos="0.0012 -0.0043 -0.0251">
                          <joint name="R_Ring3_z" type="hinge" pos="0 0 0" axis="0 0 1" user="100 10 1 150" armature="0.01" range="-180.0000 180.0000" damping="0" stiffness="0"/>
                          <joint name="R_Ring3_y" type="hinge" pos="0 0 0" axis="0 1 0" user="100 10 1 150" armature="0.01" range="-180.0000 180.0000" damping="0" stiffness="0"/>
                          <joint name="R_Ring3_x" type="hinge" pos="0 0 0" axis="1 0 0" user="100 10 1 150" armature="0.01" range="-180.0000 180.0000" damping="0" stiffness="0"/>
                          <geom type="mesh" mesh="R_Ring3_mesh" density="500" contype="1" conaffinity="1"/>
                        </body>
                      </body>
                    </body>
                    <body name="R_Thumb1" pos="0.034 -0.0404 -0.023">
                      <joint name="R_Thumb1_z" type="hinge" pos="0 0 0" axis="0 0 1" user="100 10 1 150" armature="0.01" range="-180.0000 180.0000" damping="0" stiffness="0"/>
                      <joint name="R_Thumb1_y" type="hinge" pos="0 0 0" axis="0 1 0" user="100 10 1 150" armature="0.01" range="-180.0000 180.0000" damping="0" stiffness="0"/>
                      <joint name="R_Thumb1_x" type="hinge" pos="0 0 0" axis="1 0 0" user="100 10 1 150" armature="0.01" range="-180.0000 180.0000" damping="0" stiffness="0"/>
                      <geom type="mesh" mesh="R_Thumb1_mesh" density="500" contype="1" conaffinity="1"/>
                      <body name="R_Thumb2" pos="0.0135 -0.0233 -0.0197">
                        <joint name="R_Thumb2_z" type="hinge" pos="0 0 0" axis="0 0 1" user="100 10 1 150" armature="0.01" range="-180.0000 180.0000" damping="0" stiffness="0"/>
                        <joint name="R_Thumb2_y" type="hinge" pos="0 0 0" axis="0 1 0" user="100 10 1 150" armature="0.01" range="-180.0000 180.0000" damping="0" stiffness="0"/>
                        <joint name="R_Thumb2_x" type="hinge" pos="0 0 0" axis="1 0 0" user="100 10 1 150" armature="0.01" range="-180.0000 180.0000" damping="0" stiffness="0"/>
                        <geom type="mesh" mesh="R_Thumb2_mesh" density="500" contype="1" conaffinity="1"/>
                        <body name="R_Thumb3" pos="0.0073 -0.0264 -0.0085">
                          <joint name="R_Thumb3_z" type="hinge" pos="0 0 0" axis="0 0 1" user="100 10 1 150" armature="0.01" range="-180.0000 180.0000" damping="0" stiffness="0"/>
                          <joint name="R_Thumb3_y" type="hinge" pos="0 0 0" axis="0 1 0" user="100 10 1 150" armature="0.01" range="-180.0000 180.0000" damping="0" stiffness="0"/>
                          <joint name="R_Thumb3_x" type="hinge" pos="0 0 0" axis="1 0 0" user="100 10 1 150" armature="0.01" range="-180.0000 180.0000" damping="0" stiffness="0"/>
                          <geom type="mesh" mesh="R_Thumb3_mesh" density="500" contype="1" conaffinity="1"/>
                        </body>
                      </body>
                    </body>
                  </body>
                </body>
              </body>
            </body>
          </body>
        </body>
      </body>
    </body>
  </worldbody>
  <actuator>
    <motor name="L_Hip_z" joint="L_Hip_z" gear="1"/>
    <motor name="L_Hip_y" joint="L_Hip_y" gear="1"/>
    <motor name="L_Hip_x" joint="L_Hip_x" gear="1"/>
    <motor name="L_Knee_z" joint="L_Knee_z" gear="1"/>
    <motor name="L_Knee_y" joint="L_Knee_y" gear="1"/>
    <motor name="L_Knee_x" joint="L_Knee_x" gear="1"/>
    <motor name="L_Ankle_z" joint="L_Ankle_z" gear="1"/>
    <motor name="L_Ankle_y" joint="L_Ankle_y" gear="1"/>
    <motor name="L_Ankle_x" joint="L_Ankle_x" gear="1"/>
    <motor name="L_Toe_z" joint="L_Toe_z" gear="1"/>
    <motor name="L_Toe_y" joint="L_Toe_y" gear="1"/>
    <motor name="L_Toe_x" joint="L_Toe_x" gear="1"/>
    <motor name="R_Hip_z" joint="R_Hip_z" gear="1"/>
    <motor name="R_Hip_y" joint="R_Hip_y" gear="1"/>
    <motor name="R_Hip_x" joint="R_Hip_x" gear="1"/>
    <motor name="R_Knee_z" joint="R_Knee_z" gear="1"/>
    <motor name="R_Knee_y" joint="R_Knee_y" gear="1"/>
    <motor name="R_Knee_x" joint="R_Knee_x" gear="1"/>
    <motor name="R_Ankle_z" joint="R_Ankle_z" gear="1"/>
    <motor name="R_Ankle_y" joint="R_Ankle_y" gear="1"/>
    <motor name="R_Ankle_x" joint="R_Ankle_x" gear="1"/>
    <motor name="R_Toe_z" joint="R_Toe_z" gear="1"/>
    <motor name="R_Toe_y" joint="R_Toe_y" gear="1"/>
    <motor name="R_Toe_x" joint="R_Toe_x" gear="1"/>
    <motor name="Torso_z" joint="Torso_z" gear="1"/>
    <motor name="Torso_y" joint="Torso_y" gear="1"/>
    <motor name="Torso_x" joint="Torso_x" gear="1"/>
    <motor name="Spine_z" joint="Spine_z" gear="1"/>
    <motor name="Spine_y" joint="Spine_y" gear="1"/>
    <motor name="Spine_x" joint="Spine_x" gear="1"/>
    <motor name="Chest_z" joint="Chest_z" gear="1"/>
    <motor name="Chest_y" joint="Chest_y" gear="1"/>
    <motor name="Chest_x" joint="Chest_x" gear="1"/>
    <motor name="Neck_z" joint="Neck_z" gear="1"/>
    <motor name="Neck_y" joint="Neck_y" gear="1"/>
    <motor name="Neck_x" joint="Neck_x" gear="1"/>
    <motor name="Head_z" joint="Head_z" gear="1"/>
    <motor name="Head_y" joint="Head_y" gear="1"/>
    <motor name="Head_x" joint="Head_x" gear="1"/>
    <motor name="L_Thorax_z" joint="L_Thorax_z" gear="1"/>
    <motor name="L_Thorax_y" joint="L_Thorax_y" gear="1"/>
    <motor name="L_Thorax_x" joint="L_Thorax_x" gear="1"/>
    <motor name="L_Shoulder_z" joint="L_Shoulder_z" gear="1"/>
    <motor name="L_Shoulder_y" joint="L_Shoulder_y" gear="1"/>
    <motor name="L_Shoulder_x" joint="L_Shoulder_x" gear="1"/>
    <motor name="L_Elbow_z" joint="L_Elbow_z" gear="1"/>
    <motor name="L_Elbow_y" joint="L_Elbow_y" gear="1"/>
    <motor name="L_Elbow_x" joint="L_Elbow_x" gear="1"/>
    <motor name="L_Wrist_z" joint="L_Wrist_z" gear="1"/>
    <motor name="L_Wrist_y" joint="L_Wrist_y" gear="1"/>
    <motor name="L_Wrist_x" joint="L_Wrist_x" gear="1"/>
    <motor name="L_Index1_z" joint="L_Index1_z" gear="1"/>
    <motor name="L_Index1_y" joint="L_Index1_y" gear="1"/>
    <motor name="L_Index1_x" joint="L_Index1_x" gear="1"/>
    <motor name="L_Index2_z" joint="L_Index2_z" gear="1"/>
    <motor name="L_Index2_y" joint="L_Index2_y" gear="1"/>
    <motor name="L_Index2_x" joint="L_Index2_x" gear="1"/>
    <motor name="L_Index3_z" joint="L_Index3_z" gear="1"/>
    <motor name="L_Index3_y" joint="L_Index3_y" gear="1"/>
    <motor name="L_Index3_x" joint="L_Index3_x" gear="1"/>
    <motor name="L_Middle1_z" joint="L_Middle1_z" gear="1"/>
    <motor name="L_Middle1_y" joint="L_Middle1_y" gear="1"/>
    <motor name="L_Middle1_x" joint="L_Middle1_x" gear="1"/>
    <motor name="L_Middle2_z" joint="L_Middle2_z" gear="1"/>
    <motor name="L_Middle2_y" joint="L_Middle2_y" gear="1"/>
    <motor name="L_Middle2_x" joint="L_Middle2_x" gear="1"/>
    <motor name="L_Middle3_z" joint="L_Middle3_z" gear="1"/>
    <motor name="L_Middle3_y" joint="L_Middle3_y" gear="1"/>
    <motor name="L_Middle3_x" joint="L_Middle3_x" gear="1"/>
    <motor name="L_Pinky1_z" joint="L_Pinky1_z" gear="1"/>
    <motor name="L_Pinky1_y" joint="L_Pinky1_y" gear="1"/>
    <motor name="L_Pinky1_x" joint="L_Pinky1_x" gear="1"/>
    <motor name="L_Pinky2_z" joint="L_Pinky2_z" gear="1"/>
    <motor name="L_Pinky2_y" joint="L_Pinky2_y" gear="1"/>
    <motor name="L_Pinky2_x" joint="L_Pinky2_x" gear="1"/>
    <motor name="L_Pinky3_z" joint="L_Pinky3_z" gear="1"/>
    <motor name="L_Pinky3_y" joint="L_Pinky3_y" gear="1"/>
    <motor name="L_Pinky3_x" joint="L_Pinky3_x" gear="1"/>
    <motor name="L_Ring1_z" joint="L_Ring1_z" gear="1"/>
    <motor name="L_Ring1_y" joint="L_Ring1_y" gear="1"/>
    <motor name="L_Ring1_x" joint="L_Ring1_x" gear="1"/>
    <motor name="L_Ring2_z" joint="L_Ring2_z" gear="1"/>
    <motor name="L_Ring2_y" joint="L_Ring2_y" gear="1"/>
    <motor name="L_Ring2_x" joint="L_Ring2_x" gear="1"/>
    <motor name="L_Ring3_z" joint="L_Ring3_z" gear="1"/>
    <motor name="L_Ring3_y" joint="L_Ring3_y" gear="1"/>
    <motor name="L_Ring3_x" joint="L_Ring3_x" gear="1"/>
    <motor name="L_Thumb1_z" joint="L_Thumb1_z" gear="1"/>
    <motor name="L_Thumb1_y" joint="L_Thumb1_y" gear="1"/>
    <motor name="L_Thumb1_x" joint="L_Thumb1_x" gear="1"/>
    <motor name="L_Thumb2_z" joint="L_Thumb2_z" gear="1"/>
    <motor name="L_Thumb2_y" joint="L_Thumb2_y" gear="1"/>
    <motor name="L_Thumb2_x" joint="L_Thumb2_x" gear="1"/>
    <motor name="L_Thumb3_z" joint="L_Thumb3_z" gear="1"/>
    <motor name="L_Thumb3_y" joint="L_Thumb3_y" gear="1"/>
    <motor name="L_Thumb3_x" joint="L_Thumb3_x" gear="1"/>
    <motor name="R_Thorax_z" joint="R_Thorax_z" gear="1"/>
    <motor name="R_Thorax_y" joint="R_Thorax_y" gear="1"/>
    <motor name="R_Thorax_x" joint="R_Thorax_x" gear="1"/>
    <motor name="R_Shoulder_z" joint="R_Shoulder_z" gear="1"/>
    <motor name="R_Shoulder_y" joint="R_Shoulder_y" gear="1"/>
    <motor name="R_Shoulder_x" joint="R_Shoulder_x" gear="1"/>
    <motor name="R_Elbow_z" joint="R_Elbow_z" gear="1"/>
    <motor name="R_Elbow_y" joint="R_Elbow_y" gear="1"/>
    <motor name="R_Elbow_x" joint="R_Elbow_x" gear="1"/>
    <motor name="R_Wrist_z" joint="R_Wrist_z" gear="1"/>
    <motor name="R_Wrist_y" joint="R_Wrist_y" gear="1"/>
    <motor name="R_Wrist_x" joint="R_Wrist_x" gear="1"/>
    <motor name="R_Index1_z" joint="R_Index1_z" gear="1"/>
    <motor name="R_Index1_y" joint="R_Index1_y" gear="1"/>
    <motor name="R_Index1_x" joint="R_Index1_x" gear="1"/>
    <motor name="R_Index2_z" joint="R_Index2_z" gear="1"/>
    <motor name="R_Index2_y" joint="R_Index2_y" gear="1"/>
    <motor name="R_Index2_x" joint="R_Index2_x" gear="1"/>
    <motor name="R_Index3_z" joint="R_Index3_z" gear="1"/>
    <motor name="R_Index3_y" joint="R_Index3_y" gear="1"/>
    <motor name="R_Index3_x" joint="R_Index3_x" gear="1"/>
    <motor name="R_Middle1_z" joint="R_Middle1_z" gear="1"/>
    <motor name="R_Middle1_y" joint="R_Middle1_y" gear="1"/>
    <motor name="R_Middle1_x" joint="R_Middle1_x" gear="1"/>
    <motor name="R_Middle2_z" joint="R_Middle2_z" gear="1"/>
    <motor name="R_Middle2_y" joint="R_Middle2_y" gear="1"/>
    <motor name="R_Middle2_x" joint="R_Middle2_x" gear="1"/>
    <motor name="R_Middle3_z" joint="R_Middle3_z" gear="1"/>
    <motor name="R_Middle3_y" joint="R_Middle3_y" gear="1"/>
    <motor name="R_Middle3_x" joint="R_Middle3_x" gear="1"/>
    <motor name="R_Pinky1_z" joint="R_Pinky1_z" gear="1"/>
    <motor name="R_Pinky1_y" joint="R_Pinky1_y" gear="1"/>
    <motor name="R_Pinky1_x" joint="R_Pinky1_x" gear="1"/>
    <motor name="R_Pinky2_z" joint="R_Pinky2_z" gear="1"/>
    <motor name="R_Pinky2_y" joint="R_Pinky2_y" gear="1"/>
    <motor name="R_Pinky2_x" joint="R_Pinky2_x" gear="1"/>
    <motor name="R_Pinky3_z" joint="R_Pinky3_z" gear="1"/>
    <motor name="R_Pinky3_y" joint="R_Pinky3_y" gear="1"/>
    <motor name="R_Pinky3_x" joint="R_Pinky3_x" gear="1"/>
    <motor name="R_Ring1_z" joint="R_Ring1_z" gear="1"/>
    <motor name="R_Ring1_y" joint="R_Ring1_y" gear="1"/>
    <motor name="R_Ring1_x" joint="R_Ring1_x" gear="1"/>
    <motor name="R_Ring2_z" joint="R_Ring2_z" gear="1"/>
    <motor name="R_Ring2_y" joint="R_Ring2_y" gear="1"/>
    <motor name="R_Ring2_x" joint="R_Ring2_x" gear="1"/>
    <motor name="R_Ring3_z" joint="R_Ring3_z" gear="1"/>
    <motor name="R_Ring3_y" joint="R_Ring3_y" gear="1"/>
    <motor name="R_Ring3_x" joint="R_Ring3_x" gear="1"/>
    <motor name="R_Thumb1_z" joint="R_Thumb1_z" gear="1"/>
    <motor name="R_Thumb1_y" joint="R_Thumb1_y" gear="1"/>
    <motor name="R_Thumb1_x" joint="R_Thumb1_x" gear="1"/>
    <motor name="R_Thumb2_z" joint="R_Thumb2_z" gear="1"/>
    <motor name="R_Thumb2_y" joint="R_Thumb2_y" gear="1"/>
    <motor name="R_Thumb2_x" joint="R_Thumb2_x" gear="1"/>
    <motor name="R_Thumb3_z" joint="R_Thumb3_z" gear="1"/>
    <motor name="R_Thumb3_y" joint="R_Thumb3_y" gear="1"/>
    <motor name="R_Thumb3_x" joint="R_Thumb3_x" gear="1"/>
  </actuator>
  <contact>
    <exclude body1="Torso" body2="Chest"/>
    <exclude body1="Head" body2="Chest"/>
    <exclude body1="R_Knee" body2="R_Toe"/>
    <exclude body1="R_Knee" body2="L_Ankle"/>
    <exclude body1="R_Knee" body2="L_Toe"/>
    <exclude body1="L_Knee" body2="L_Toe"/>
    <exclude body1="L_Knee" body2="R_Ankle"/>
    <exclude body1="L_Knee" body2="R_Toe"/>
    <exclude body1="L_Shoulder" body2="Chest"/>
    <exclude body1="R_Shoulder" body2="Chest"/>
  </contact>
  <sensor/>
  <size njmax="2500" nconmax="500"/>
</mujoco>
