<mujoco model="humanoid">
  <compiler coordinate="local"/>
  <default>
    <joint damping="0.0" armature="0.01" stiffness="0.0" limited="true"/>
    <geom conaffinity="1" condim="3" contype="7" margin="0.001" rgba="0.8 0.6 .4 1"/>
  </default>
  <asset>
    <texture type="skybox" builtin="gradient" rgb1=".4 .5 .6" rgb2="0 0 0" width="100" height="100"/>
    <texture builtin="flat" height="1278" mark="cross" markrgb="1 1 1" name="texgeom" random="0.01" rgb1="0.8 0.6 0.4" rgb2="0.8 0.6 0.4" type="cube" width="127"/>
    <texture builtin="checker" height="100" name="texplane" rgb1="0 0 0" rgb2="0.8 0.8 0.8" type="2d" width="100"/>
    <material name="MatPlane" reflectance="0.5" shininess="1" specular="1" texrepeat="60 60" texture="texplane"/>
    <material name="geom" texture="texgeom" texuniform="true"/>
  </asset>
  <worldbody>
    <light cutoff="100" diffuse="1 1 1" dir="-0 0 -1.3" directional="true" exponent="1" pos="0 0 1.3" specular=".1 .1 .1"/>
    <geom conaffinity="1" condim="3" name="floor" pos="0 0 0" rgba="0.8 0.9 0.8 1" size="100 100 .2" type="plane" material="MatPlane"/>
    <body name="Pelvis" pos="0.0019 -0.3994 0.0187">
      <freejoint name="Pelvis"/>
      <geom type="sphere" contype="1" conaffinity="1" density="500" size="0.1220" pos="0.0000 0.0000 0.0000" name="Pelvis"/>
      <body name="L_Hip" pos="-0.0244 0.0655 -0.1033">
        <joint name="L_Hip_x" type="hinge" pos="0 0 0" axis="1 0 0" user="250 2.5 1 500 10 2" armature="0.01" range="-180.0000 180.0000" damping="0" stiffness="0"/>
        <joint name="L_Hip_y" type="hinge" pos="0 0 0" axis="0 1 0" user="250 2.5 1 500 10 2" armature="0.01" range="-180.0000 180.0000" damping="0" stiffness="0"/>
        <joint name="L_Hip_z" type="hinge" pos="0 0 0" axis="0 0 1" user="250 2.5 1 500 10 2" armature="0.01" range="-180.0000 180.0000" damping="0" stiffness="0"/>
        <geom type="capsule" contype="1" conaffinity="1" density="500" fromto="0.0012 0.0141 -0.0769 0.0050 0.0564 -0.3074" size="0.0709" name="L_Hip"/>
        <body name="L_Knee" pos="0.0062 0.0706 -0.3843">
          <joint name="L_Knee_x" type="hinge" pos="0 0 0" axis="1 0 0" user="250 2.5 1 500 10 2" armature="0.01" range="-180.0000 180.0000" damping="0" stiffness="0"/>
          <joint name="L_Knee_y" type="hinge" pos="0 0 0" axis="0 1 0" user="250 2.5 1 500 10 2" armature="0.01" range="-180.0000 180.0000" damping="0" stiffness="0"/>
          <joint name="L_Knee_z" type="hinge" pos="0 0 0" axis="0 0 1" user="250 2.5 1 500 10 2" armature="0.01" range="-180.0000 180.0000" damping="0" stiffness="0"/>
          <geom type="capsule" contype="1" conaffinity="1" density="500" fromto="-0.0095 -0.0115 -0.0853 -0.0382 -0.0459 -0.3411" size="0.0643" name="L_Knee"/>
          <body name="L_Ankle" pos="-0.0477 -0.0574 -0.4264">
            <joint name="L_Ankle_x" type="hinge" pos="0 0 0" axis="1 0 0" user="150 2.5 1 500 10 2" armature="0.01" range="-180.0000 180.0000" damping="0" stiffness="0"/>
            <joint name="L_Ankle_y" type="hinge" pos="0 0 0" axis="0 1 0" user="150 2.5 1 500 10 2" armature="0.01" range="-180.0000 180.0000" damping="0" stiffness="0"/>
            <joint name="L_Ankle_z" type="hinge" pos="0 0 0" axis="0 0 1" user="150 2.5 1 500 10 2" armature="0.01" range="-180.0000 180.0000" damping="0" stiffness="0"/>
            <geom type="box" contype="1" conaffinity="1" density="500" pos="0.0734 0.0245 -0.0311" size="0.1053 0.0589 0.0237" quat="1.0000 0.0000 0.0000 0.0000" name="L_Ankle"/>
            <body name="L_Toe" pos="0.1468 0.0491 -0.0621">
              <joint name="L_Toe_x" type="hinge" pos="0 0 0" axis="1 0 0" user="150 1 1 500 1 1" armature="0.01" range="-180.0000 180.0000" damping="0" stiffness="0"/>
              <joint name="L_Toe_y" type="hinge" pos="0 0 0" axis="0 1 0" user="150 1 1 500 1 1" armature="0.01" range="-180.0000 180.0000" damping="0" stiffness="0"/>
              <joint name="L_Toe_z" type="hinge" pos="0 0 0" axis="0 0 1" user="150 1 1 500 1 1" armature="0.01" range="-180.0000 180.0000" damping="0" stiffness="0"/>
              <geom type="box" contype="1" conaffinity="1" density="500" pos="0.0744 -0.0245 0.0311" size="0.0234 0.0567 0.0237" quat="1.0000 0.0000 0.0000 0.0000" name="L_Toe"/>
            </body>
          </body>
        </body>
      </body>
      <body name="R_Hip" pos="-0.0152 -0.068 -0.1155">
        <joint name="R_Hip_x" type="hinge" pos="0 0 0" axis="1 0 0" user="250 2.5 1 500 10 2" armature="0.01" range="-180.0000 180.0000" damping="0" stiffness="0"/>
        <joint name="R_Hip_y" type="hinge" pos="0 0 0" axis="0 1 0" user="250 2.5 1 500 10 2" armature="0.01" range="-180.0000 180.0000" damping="0" stiffness="0"/>
        <joint name="R_Hip_z" type="hinge" pos="0 0 0" axis="0 0 1" user="250 2.5 1 500 10 2" armature="0.01" range="-180.0000 180.0000" damping="0" stiffness="0"/>
        <geom type="capsule" contype="1" conaffinity="1" density="500" fromto="-0.0008 -0.0101 -0.0734 -0.0031 -0.0404 -0.2934" size="0.0709" name="R_Hip"/>
        <body name="R_Knee" pos="-0.0038 -0.0504 -0.3668">
          <joint name="R_Knee_x" type="hinge" pos="0 0 0" axis="1 0 0" user="250 2.5 1 500 10 2" armature="0.01" range="-180.0000 180.0000" damping="0" stiffness="0"/>
          <joint name="R_Knee_y" type="hinge" pos="0 0 0" axis="0 1 0" user="250 2.5 1 500 10 2" armature="0.01" range="-180.0000 180.0000" damping="0" stiffness="0"/>
          <joint name="R_Knee_z" type="hinge" pos="0 0 0" axis="0 0 1" user="250 2.5 1 500 10 2" armature="0.01" range="-180.0000 180.0000" damping="0" stiffness="0"/>
          <geom type="capsule" contype="1" conaffinity="1" density="500" fromto="-0.0093 0.0044 -0.0879 -0.0372 0.0174 -0.3515" size="0.0644" name="R_Knee"/>
          <body name="R_Ankle" pos="-0.0465 0.0218 -0.4394">
            <joint name="R_Ankle_x" type="hinge" pos="0 0 0" axis="1 0 0" user="150 1 1 500 10 2" armature="0.01" range="-180.0000 180.0000" damping="0" stiffness="0"/>
            <joint name="R_Ankle_y" type="hinge" pos="0 0 0" axis="0 1 0" user="150 1 1 500 10 2" armature="0.01" range="-180.0000 180.0000" damping="0" stiffness="0"/>
            <joint name="R_Ankle_z" type="hinge" pos="0 0 0" axis="0 0 1" user="150 1 1 500 10 2" armature="0.01" range="-180.0000 180.0000" damping="0" stiffness="0"/>
            <geom type="box" contype="1" conaffinity="1" density="500" pos="0.0772 -0.0185 -0.0304" size="0.1053 0.0589 0.0281" quat="1.0000 0.0000 0.0000 0.0000" name="R_Ankle"/>
            <body name="R_Toe" pos="0.1543 -0.0371 -0.0608">
              <joint name="R_Toe_x" type="hinge" pos="0 0 0" axis="1 0 0" user="150 1 1 500 1 1" armature="0.01" range="-180.0000 180.0000" damping="0" stiffness="0"/>
              <joint name="R_Toe_y" type="hinge" pos="0 0 0" axis="0 1 0" user="150 1 1 500 1 1" armature="0.01" range="-180.0000 180.0000" damping="0" stiffness="0"/>
              <joint name="R_Toe_z" type="hinge" pos="0 0 0" axis="0 0 1" user="150 1 1 500 1 1" armature="0.01" range="-180.0000 180.0000" damping="0" stiffness="0"/>
              <geom type="box" contype="1" conaffinity="1" density="500" pos="0.0782 0.0185 0.0260" size="0.0228 0.0567 0.0237" quat="1.0000 0.0000 0.0000 0.0000" name="R_Toe"/>
            </body>
          </body>
        </body>
      </body>
      <body name="Torso" pos="-0.0468 -0.0042 0.1262">
        <joint name="Torso_x" type="hinge" pos="0 0 0" axis="1 0 0" user="500 5 1 500 10 2" armature="0.01" range="-180.0000 180.0000" damping="0" stiffness="0"/>
        <joint name="Torso_y" type="hinge" pos="0 0 0" axis="0 1 0" user="500 5 1 500 10 2" armature="0.01" range="-180.0000 180.0000" damping="0" stiffness="0"/>
        <joint name="Torso_z" type="hinge" pos="0 0 0" axis="0 0 1" user="500 5 1 500 10 2" armature="0.01" range="-180.0000 180.0000" damping="0" stiffness="0"/>
        <geom type="capsule" contype="1" conaffinity="1" density="500" fromto="0.0001 0.0073 0.0756 0.0001 0.0090 0.0924" size="0.0884" name="Torso"/>
        <body name="Spine" pos="0.0002 0.0163 0.1681">
          <joint name="Spine_x" type="hinge" pos="0 0 0" axis="1 0 0" user="500 5 1 500 10 2" armature="0.01" range="-180.0000 180.0000" damping="0" stiffness="0"/>
          <joint name="Spine_y" type="hinge" pos="0 0 0" axis="0 1 0" user="500 5 1 500 10 2" armature="0.01" range="-180.0000 180.0000" damping="0" stiffness="0"/>
          <joint name="Spine_z" type="hinge" pos="0 0 0" axis="0 0 1" user="500 5 1 500 10 2" armature="0.01" range="-180.0000 180.0000" damping="0" stiffness="0"/>
          <geom type="capsule" contype="1" conaffinity="1" density="500" fromto="0.0134 -0.0050 0.0291 0.0164 -0.0061 0.0356" size="0.1022" name="Spine"/>
          <body name="Chest" pos="0.0298 -0.0111 0.0647">
            <joint name="Chest_x" type="hinge" pos="0 0 0" axis="1 0 0" user="500 5 1 500 10 2" armature="0.01" range="-180.0000 180.0000" damping="0" stiffness="0"/>
            <joint name="Chest_y" type="hinge" pos="0 0 0" axis="0 1 0" user="500 5 1 500 10 2" armature="0.01" range="-180.0000 180.0000" damping="0" stiffness="0"/>
            <joint name="Chest_z" type="hinge" pos="0 0 0" axis="0 0 1" user="500 5 1 500 10 2" armature="0.01" range="-180.0000 180.0000" damping="0" stiffness="0"/>
            <geom type="capsule" contype="1" conaffinity="1" density="500" fromto="-0.0067 -0.0028 0.0506 -0.0082 -0.0035 0.0618" size="0.1172" name="Chest"/>
            <body name="Neck" pos="-0.0313 -0.0117 0.1742">
              <joint name="Neck_x" type="hinge" pos="0 0 0" axis="1 0 0" user="150 1 1 250 50 4" armature="0.01" range="-180.0000 180.0000" damping="0" stiffness="0"/>
              <joint name="Neck_y" type="hinge" pos="0 0 0" axis="0 1 0" user="150 1 1 250 50 4" armature="0.01" range="-180.0000 180.0000" damping="0" stiffness="0"/>
              <joint name="Neck_z" type="hinge" pos="0 0 0" axis="0 0 1" user="150 1 1 250 50 4" armature="0.01" range="-180.0000 180.0000" damping="0" stiffness="0"/>
              <geom type="capsule" contype="1" conaffinity="1" density="500" fromto="0.0045 0.0052 0.0293 0.0178 0.0210 0.1173" size="0.0479" name="Neck"/>
              <body name="Head" pos="0.0223 0.0262 0.1466">
                <joint name="Head_x" type="hinge" pos="0 0 0" axis="1 0 0" user="150 1 1 250 50 4" armature="0.01" range="-180.0000 180.0000" damping="0" stiffness="0"/>
                <joint name="Head_y" type="hinge" pos="0 0 0" axis="0 1 0" user="150 1 1 250 50 4" armature="0.01" range="-180.0000 180.0000" damping="0" stiffness="0"/>
                <joint name="Head_z" type="hinge" pos="0 0 0" axis="0 0 1" user="150 1 1 250 50 4" armature="0.01" range="-180.0000 180.0000" damping="0" stiffness="0"/>
                <geom type="sphere" contype="1" conaffinity="1" density="500" size="0.1149" pos="0.0000 0.0000 0.0000" name="Head"/>
              </body>
            </body>
            <body name="L_Thorax" pos="-0.005 0.0407 0.081">
              <joint name="L_Thorax_x" type="hinge" pos="0 0 0" axis="1 0 0" user="200 2 1 500 50 4" armature="0.01" range="-180.0000 180.0000" damping="0" stiffness="0"/>
              <joint name="L_Thorax_y" type="hinge" pos="0 0 0" axis="0 1 0" user="200 2 1 500 50 4" armature="0.01" range="-180.0000 180.0000" damping="0" stiffness="0"/>
              <joint name="L_Thorax_z" type="hinge" pos="0 0 0" axis="0 0 1" user="200 2 1 500 50 4" armature="0.01" range="-180.0000 180.0000" damping="0" stiffness="0"/>
              <geom type="capsule" contype="1" conaffinity="1" density="500" fromto="-0.0046 0.0280 0.0130 -0.0182 0.1120 0.0521" size="0.0533" name="L_Thorax"/>
              <body name="L_Shoulder" pos="-0.0228 0.14 0.0651">
                <joint name="L_Shoulder_x" type="hinge" pos="0 0 0" axis="1 0 0" user="200 2 1 500 50 4" armature="0.01" range="-180.0000 180.0000" damping="0" stiffness="0"/>
                <joint name="L_Shoulder_y" type="hinge" pos="0 0 0" axis="0 1 0" user="200 2 1 500 50 4" armature="0.01" range="-180.0000 180.0000" damping="0" stiffness="0"/>
                <joint name="L_Shoulder_z" type="hinge" pos="0 0 0" axis="0 0 1" user="200 2 1 500 50 4" armature="0.01" range="-180.0000 180.0000" damping="0" stiffness="0"/>
                <geom type="capsule" contype="1" conaffinity="1" density="500" fromto="-0.0106 0.0513 -0.0171 -0.0424 0.2051 -0.0684" size="0.0619" name="L_Shoulder"/>
                <body name="L_Elbow" pos="-0.0531 0.2564 -0.0855">
                  <joint name="L_Elbow_x" type="hinge" pos="0 0 0" axis="1 0 0" user="150 1 1 150 10 2" armature="0.01" range="-720.0000 720.0000" damping="0" stiffness="0"/>
                  <joint name="L_Elbow_y" type="hinge" pos="0 0 0" axis="0 1 0" user="150 1 1 150 10 2" armature="0.01" range="-720.0000 720.0000" damping="0" stiffness="0"/>
                  <joint name="L_Elbow_z" type="hinge" pos="0 0 0" axis="0 0 1" user="150 1 1 150 10 2" armature="0.01" range="-720.0000 720.0000" damping="0" stiffness="0"/>
                  <geom type="capsule" contype="1" conaffinity="1" density="500" fromto="0.0008 0.0568 0.0060 0.0030 0.2272 0.0238" size="0.0481" name="L_Elbow"/>
                  <body name="L_Wrist" pos="0.0038 0.284 0.0298">
                    <joint name="L_Wrist_x" type="hinge" pos="0 0 0" axis="1 0 0" user="100 1 1 150 1 1" armature="0.01" range="-180.0000 180.0000" damping="0" stiffness="0"/>
                    <joint name="L_Wrist_y" type="hinge" pos="0 0 0" axis="0 1 0" user="100 1 1 150 1 1" armature="0.01" range="-180.0000 180.0000" damping="0" stiffness="0"/>
                    <joint name="L_Wrist_z" type="hinge" pos="0 0 0" axis="0 0 1" user="100 1 1 150 1 1" armature="0.01" range="-180.0000 180.0000" damping="0" stiffness="0"/>
                    <geom type="box" contype="1" conaffinity="1" density="500" pos="-0.0033 0.0500 -0.0060" size="0.0491 0.0509 0.0092" quat="1.0000 0.0000 0.0000 0.0000" name="L_Wrist"/>
                    <body name="L_Index1" pos="0.0241 0.1178 -0.0089">
                      <joint name="L_Index1_x" type="hinge" pos="0 0 0" axis="1 0 0" user="100 10 1 150" armature="0.01" range="-180.0000 180.0000" damping="0" stiffness="0"/>
                      <joint name="L_Index1_y" type="hinge" pos="0 0 0" axis="0 1 0" user="100 10 1 150" armature="0.01" range="-180.0000 180.0000" damping="0" stiffness="0"/>
                      <joint name="L_Index1_z" type="hinge" pos="0 0 0" axis="0 0 1" user="100 10 1 150" armature="0.01" range="-180.0000 180.0000" damping="0" stiffness="0"/>
                      <geom type="capsule" contype="1" conaffinity="1" density="500" fromto="0.0004 0.0068 -0.0026 0.0018 0.0271 -0.0105" size="0.0107" name="L_Index1"/>
                      <body name="L_Index2" pos="0.0022 0.0339 -0.0131">
                        <joint name="L_Index2_x" type="hinge" pos="0 0 0" axis="1 0 0" user="100 10 1 150" armature="0.01" range="-180.0000 180.0000" damping="0" stiffness="0"/>
                        <joint name="L_Index2_y" type="hinge" pos="0 0 0" axis="0 1 0" user="100 10 1 150" armature="0.01" range="-180.0000 180.0000" damping="0" stiffness="0"/>
                        <joint name="L_Index2_z" type="hinge" pos="0 0 0" axis="0 0 1" user="100 10 1 150" armature="0.01" range="-180.0000 180.0000" damping="0" stiffness="0"/>
                        <geom type="capsule" contype="1" conaffinity="1" density="500" fromto="-0.0006 0.0014 -0.0049 -0.0025 0.0055 -0.0194" size="0.0085" name="L_Index2"/>
                        <body name="L_Index3" pos="-0.0031 0.0068 -0.0243">
                          <joint name="L_Index3_x" type="hinge" pos="0 0 0" axis="1 0 0" user="100 10 1 150" armature="0.01" range="-180.0000 180.0000" damping="0" stiffness="0"/>
                          <joint name="L_Index3_y" type="hinge" pos="0 0 0" axis="0 1 0" user="100 10 1 150" armature="0.01" range="-180.0000 180.0000" damping="0" stiffness="0"/>
                          <joint name="L_Index3_z" type="hinge" pos="0 0 0" axis="0 0 1" user="100 10 1 150" armature="0.01" range="-180.0000 180.0000" damping="0" stiffness="0"/>
                          <geom type="capsule" contype="1" conaffinity="1" density="500" fromto="-0.0002 0.0018 -0.0045 -0.0009 0.0071 -0.0178" size="0.0077" name="L_Index3"/>
                        </body>
                      </body>
                    </body>
                    <body name="L_Middle1" pos="-0.0034 0.1265 -0.0053">
                      <joint name="L_Middle1_x" type="hinge" pos="0 0 0" axis="1 0 0" user="100 10 1 150" armature="0.01" range="-180.0000 180.0000" damping="0" stiffness="0"/>
                      <joint name="L_Middle1_y" type="hinge" pos="0 0 0" axis="0 1 0" user="100 10 1 150" armature="0.01" range="-180.0000 180.0000" damping="0" stiffness="0"/>
                      <joint name="L_Middle1_z" type="hinge" pos="0 0 0" axis="0 0 1" user="100 10 1 150" armature="0.01" range="-180.0000 180.0000" damping="0" stiffness="0"/>
                      <geom type="capsule" contype="1" conaffinity="1" density="500" fromto="-0.0010 0.0059 -0.0034 -0.0041 0.0238 -0.0137" size="0.0109" name="L_Middle1"/>
                      <body name="L_Middle2" pos="-0.0051 0.0297 -0.0171">
                        <joint name="L_Middle2_x" type="hinge" pos="0 0 0" axis="1 0 0" user="100 10 1 150" armature="0.01" range="-180.0000 180.0000" damping="0" stiffness="0"/>
                        <joint name="L_Middle2_y" type="hinge" pos="0 0 0" axis="0 1 0" user="100 10 1 150" armature="0.01" range="-180.0000 180.0000" damping="0" stiffness="0"/>
                        <joint name="L_Middle2_z" type="hinge" pos="0 0 0" axis="0 0 1" user="100 10 1 150" armature="0.01" range="-180.0000 180.0000" damping="0" stiffness="0"/>
                        <geom type="capsule" contype="1" conaffinity="1" density="500" fromto="-0.0004 0.0010 -0.0052 -0.0017 0.0040 -0.0209" size="0.0082" name="L_Middle2"/>
                        <body name="L_Middle3" pos="-0.0021 0.005 -0.0262">
                          <joint name="L_Middle3_x" type="hinge" pos="0 0 0" axis="1 0 0" user="100 10 1 150" armature="0.01" range="-180.0000 180.0000" damping="0" stiffness="0"/>
                          <joint name="L_Middle3_y" type="hinge" pos="0 0 0" axis="0 1 0" user="100 10 1 150" armature="0.01" range="-180.0000 180.0000" damping="0" stiffness="0"/>
                          <joint name="L_Middle3_z" type="hinge" pos="0 0 0" axis="0 0 1" user="100 10 1 150" armature="0.01" range="-180.0000 180.0000" damping="0" stiffness="0"/>
                          <geom type="capsule" contype="1" conaffinity="1" density="500" fromto="-0.0000 0.0014 -0.0048 -0.0001 0.0056 -0.0193" size="0.0074" name="L_Middle3"/>
                        </body>
                      </body>
                    </body>
                    <body name="L_Pinky1" pos="-0.0525 0.0965 -0.0153">
                      <joint name="L_Pinky1_x" type="hinge" pos="0 0 0" axis="1 0 0" user="100 10 1 150" armature="0.01" range="-180.0000 180.0000" damping="0" stiffness="0"/>
                      <joint name="L_Pinky1_y" type="hinge" pos="0 0 0" axis="0 1 0" user="100 10 1 150" armature="0.01" range="-180.0000 180.0000" damping="0" stiffness="0"/>
                      <joint name="L_Pinky1_z" type="hinge" pos="0 0 0" axis="0 0 1" user="100 10 1 150" armature="0.01" range="-180.0000 180.0000" damping="0" stiffness="0"/>
                      <geom type="capsule" contype="1" conaffinity="1" density="500" fromto="-0.0010 0.0027 -0.0034 -0.0041 0.0108 -0.0137" size="0.0081" name="L_Pinky1"/>
                      <body name="L_Pinky2" pos="-0.0051 0.0136 -0.0171">
                        <joint name="L_Pinky2_x" type="hinge" pos="0 0 0" axis="1 0 0" user="100 10 1 150" armature="0.01" range="-180.0000 180.0000" damping="0" stiffness="0"/>
                        <joint name="L_Pinky2_y" type="hinge" pos="0 0 0" axis="0 1 0" user="100 10 1 150" armature="0.01" range="-180.0000 180.0000" damping="0" stiffness="0"/>
                        <joint name="L_Pinky2_z" type="hinge" pos="0 0 0" axis="0 0 1" user="100 10 1 150" armature="0.01" range="-180.0000 180.0000" damping="0" stiffness="0"/>
                        <geom type="capsule" contype="1" conaffinity="1" density="500" fromto="0.0002 0.0008 -0.0042 0.0008 0.0030 -0.0169" size="0.0072" name="L_Pinky2"/>
                        <body name="L_Pinky3" pos="0.0011 0.0038 -0.0212">
                          <joint name="L_Pinky3_x" type="hinge" pos="0 0 0" axis="1 0 0" user="100 10 1 150" armature="0.01" range="-180.0000 180.0000" damping="0" stiffness="0"/>
                          <joint name="L_Pinky3_y" type="hinge" pos="0 0 0" axis="0 1 0" user="100 10 1 150" armature="0.01" range="-180.0000 180.0000" damping="0" stiffness="0"/>
                          <joint name="L_Pinky3_z" type="hinge" pos="0 0 0" axis="0 0 1" user="100 10 1 150" armature="0.01" range="-180.0000 180.0000" damping="0" stiffness="0"/>
                          <geom type="capsule" contype="1" conaffinity="1" density="500" fromto="0.0006 0.0012 -0.0038 0.0024 0.0046 -0.0153" size="0.0057" name="L_Pinky3"/>
                        </body>
                      </body>
                    </body>
                    <body name="L_Ring1" pos="-0.0321 0.1123 -0.0085">
                      <joint name="L_Ring1_x" type="hinge" pos="0 0 0" axis="1 0 0" user="100 10 1 150" armature="0.01" range="-180.0000 180.0000" damping="0" stiffness="0"/>
                      <joint name="L_Ring1_y" type="hinge" pos="0 0 0" axis="0 1 0" user="100 10 1 150" armature="0.01" range="-180.0000 180.0000" damping="0" stiffness="0"/>
                      <joint name="L_Ring1_z" type="hinge" pos="0 0 0" axis="0 0 1" user="100 10 1 150" armature="0.01" range="-180.0000 180.0000" damping="0" stiffness="0"/>
                      <geom type="capsule" contype="1" conaffinity="1" density="500" fromto="-0.0002 0.0053 -0.0037 -0.0010 0.0212 -0.0149" size="0.0093" name="L_Ring1"/>
                      <body name="L_Ring2" pos="-0.0012 0.0265 -0.0187">
                        <joint name="L_Ring2_x" type="hinge" pos="0 0 0" axis="1 0 0" user="100 10 1 150" armature="0.01" range="-180.0000 180.0000" damping="0" stiffness="0"/>
                        <joint name="L_Ring2_y" type="hinge" pos="0 0 0" axis="0 1 0" user="100 10 1 150" armature="0.01" range="-180.0000 180.0000" damping="0" stiffness="0"/>
                        <joint name="L_Ring2_z" type="hinge" pos="0 0 0" axis="0 0 1" user="100 10 1 150" armature="0.01" range="-180.0000 180.0000" damping="0" stiffness="0"/>
                        <geom type="capsule" contype="1" conaffinity="1" density="500" fromto="0.0004 0.0008 -0.0052 0.0014 0.0033 -0.0210" size="0.0083" name="L_Ring2"/>
                        <body name="L_Ring3" pos="0.0018 0.0041 -0.0262">
                          <joint name="L_Ring3_x" type="hinge" pos="0 0 0" axis="1 0 0" user="100 10 1 150" armature="0.01" range="-180.0000 180.0000" damping="0" stiffness="0"/>
                          <joint name="L_Ring3_y" type="hinge" pos="0 0 0" axis="0 1 0" user="100 10 1 150" armature="0.01" range="-180.0000 180.0000" damping="0" stiffness="0"/>
                          <joint name="L_Ring3_z" type="hinge" pos="0 0 0" axis="0 0 1" user="100 10 1 150" armature="0.01" range="-180.0000 180.0000" damping="0" stiffness="0"/>
                          <geom type="capsule" contype="1" conaffinity="1" density="500" fromto="0.0008 0.0012 -0.0048 0.0030 0.0049 -0.0194" size="0.0068" name="L_Ring3"/>
                        </body>
                      </body>
                    </body>
                    <body name="L_Thumb1" pos="0.0312 0.0465 -0.0219">
                      <joint name="L_Thumb1_x" type="hinge" pos="0 0 0" axis="1 0 0" user="100 10 1 150" armature="0.01" range="-180.0000 180.0000" damping="0" stiffness="0"/>
                      <joint name="L_Thumb1_y" type="hinge" pos="0 0 0" axis="0 1 0" user="100 10 1 150" armature="0.01" range="-180.0000 180.0000" damping="0" stiffness="0"/>
                      <joint name="L_Thumb1_z" type="hinge" pos="0 0 0" axis="0 0 1" user="100 10 1 150" armature="0.01" range="-180.0000 180.0000" damping="0" stiffness="0"/>
                      <geom type="capsule" contype="1" conaffinity="1" density="500" fromto="0.0031 0.0049 -0.0040 0.0122 0.0197 -0.0160" size="0.0146" name="L_Thumb1"/>
                      <body name="L_Thumb2" pos="0.0153 0.0246 -0.02">
                        <joint name="L_Thumb2_x" type="hinge" pos="0 0 0" axis="1 0 0" user="100 10 1 150" armature="0.01" range="-180.0000 180.0000" damping="0" stiffness="0"/>
                        <joint name="L_Thumb2_y" type="hinge" pos="0 0 0" axis="0 1 0" user="100 10 1 150" armature="0.01" range="-180.0000 180.0000" damping="0" stiffness="0"/>
                        <joint name="L_Thumb2_z" type="hinge" pos="0 0 0" axis="0 0 1" user="100 10 1 150" armature="0.01" range="-180.0000 180.0000" damping="0" stiffness="0"/>
                        <geom type="capsule" contype="1" conaffinity="1" density="500" fromto="0.0017 0.0053 -0.0019 0.0067 0.0212 -0.0077" size="0.0112" name="L_Thumb2"/>
                        <body name="L_Thumb3" pos="0.0084 0.0265 -0.0096">
                          <joint name="L_Thumb3_x" type="hinge" pos="0 0 0" axis="1 0 0" user="100 10 1 150" armature="0.01" range="-180.0000 180.0000" damping="0" stiffness="0"/>
                          <joint name="L_Thumb3_y" type="hinge" pos="0 0 0" axis="0 1 0" user="100 10 1 150" armature="0.01" range="-180.0000 180.0000" damping="0" stiffness="0"/>
                          <joint name="L_Thumb3_z" type="hinge" pos="0 0 0" axis="0 0 1" user="100 10 1 150" armature="0.01" range="-180.0000 180.0000" damping="0" stiffness="0"/>
                          <geom type="capsule" contype="1" conaffinity="1" density="500" fromto="0.0021 0.0057 -0.0015 0.0083 0.0228 -0.0061" size="0.0102" name="L_Thumb3"/>
                        </body>
                      </body>
                    </body>
                  </body>
                </body>
              </body>
            </body>
            <body name="R_Thorax" pos="-0.0086 -0.0479 0.082">
              <joint name="R_Thorax_x" type="hinge" pos="0 0 0" axis="1 0 0" user="200 2 1 150 10 2" armature="0.01" range="-180.0000 180.0000" damping="0" stiffness="0"/>
              <joint name="R_Thorax_y" type="hinge" pos="0 0 0" axis="0 1 0" user="200 2 1 150 10 2" armature="0.01" range="-180.0000 180.0000" damping="0" stiffness="0"/>
              <joint name="R_Thorax_z" type="hinge" pos="0 0 0" axis="0 0 1" user="200 2 1 150 10 2" armature="0.01" range="-180.0000 180.0000" damping="0" stiffness="0"/>
              <geom type="capsule" contype="1" conaffinity="1" density="500" fromto="-0.0041 -0.0259 0.0123 -0.0166 -0.1034 0.0491" size="0.0629" name="R_Thorax"/>
              <body name="R_Shoulder" pos="-0.0207 -0.1293 0.0614">
                <joint name="R_Shoulder_x" type="hinge" pos="0 0 0" axis="1 0 0" user="200 2 1 250 10 2" armature="0.01" range="-180.0000 180.0000" damping="0" stiffness="0"/>
                <joint name="R_Shoulder_y" type="hinge" pos="0 0 0" axis="0 1 0" user="200 2 1 250 10 2" armature="0.01" range="-180.0000 180.0000" damping="0" stiffness="0"/>
                <joint name="R_Shoulder_z" type="hinge" pos="0 0 0" axis="0 0 1" user="200 2 1 250 10 2" armature="0.01" range="-180.0000 180.0000" damping="0" stiffness="0"/>
                <geom type="capsule" contype="1" conaffinity="1" density="500" fromto="-0.0073 -0.0549 -0.0096 -0.0293 -0.2196 -0.0383" size="0.0614" name="R_Shoulder"/>
                <body name="R_Elbow" pos="-0.0366 -0.2745 -0.0479">
                  <joint name="R_Elbow_x" type="hinge" pos="0 0 0" axis="1 0 0" user="150 1 1 150 10 2" armature="0.01" range="-720.0000 720.0000" damping="0" stiffness="0"/>
                  <joint name="R_Elbow_y" type="hinge" pos="0 0 0" axis="0 1 0" user="150 1 1 150 10 2" armature="0.01" range="-720.0000 720.0000" damping="0" stiffness="0"/>
                  <joint name="R_Elbow_z" type="hinge" pos="0 0 0" axis="0 0 1" user="150 1 1 150 10 2" armature="0.01" range="-720.0000 720.0000" damping="0" stiffness="0"/>
                  <geom type="capsule" contype="1" conaffinity="1" density="500" fromto="-0.0020 -0.0552 -0.0002 -0.0080 -0.2207 -0.0009" size="0.0493" name="R_Elbow"/>
                  <body name="R_Wrist" pos="-0.01 -0.2758 -0.0011">
                    <joint name="R_Wrist_x" type="hinge" pos="0 0 0" axis="1 0 0" user="100 1 1 150 1 1" armature="0.01" range="-180.0000 180.0000" damping="0" stiffness="0"/>
                    <joint name="R_Wrist_y" type="hinge" pos="0 0 0" axis="0 1 0" user="100 1 1 150 1 1" armature="0.01" range="-180.0000 180.0000" damping="0" stiffness="0"/>
                    <joint name="R_Wrist_z" type="hinge" pos="0 0 0" axis="0 0 1" user="100 1 1 150 1 1" armature="0.01" range="-180.0000 180.0000" damping="0" stiffness="0"/>
                    <geom type="box" contype="1" conaffinity="1" density="500" pos="-0.0039 -0.0496 -0.0080" size="0.0491 0.0523 0.0093" quat="1.0000 0.0000 0.0000 0.0000" name="R_Wrist"/>
                    <body name="R_Index1" pos="0.0228 -0.1171 -0.0129">
                      <joint name="R_Index1_x" type="hinge" pos="0 0 0" axis="1 0 0" user="100 10 1 150" armature="0.01" range="-180.0000 180.0000" damping="0" stiffness="0"/>
                      <joint name="R_Index1_y" type="hinge" pos="0 0 0" axis="0 1 0" user="100 10 1 150" armature="0.01" range="-180.0000 180.0000" damping="0" stiffness="0"/>
                      <joint name="R_Index1_z" type="hinge" pos="0 0 0" axis="0 0 1" user="100 10 1 150" armature="0.01" range="-180.0000 180.0000" damping="0" stiffness="0"/>
                      <geom type="capsule" contype="1" conaffinity="1" density="500" fromto="0.0004 -0.0068 -0.0026 0.0018 -0.0271 -0.0105" size="0.0107" name="R_Index1"/>
                      <body name="R_Index2" pos="0.0022 -0.0339 -0.0131">
                        <joint name="R_Index2_x" type="hinge" pos="0 0 0" axis="1 0 0" user="100 10 1 150" armature="0.01" range="-180.0000 180.0000" damping="0" stiffness="0"/>
                        <joint name="R_Index2_y" type="hinge" pos="0 0 0" axis="0 1 0" user="100 10 1 150" armature="0.01" range="-180.0000 180.0000" damping="0" stiffness="0"/>
                        <joint name="R_Index2_z" type="hinge" pos="0 0 0" axis="0 0 1" user="100 10 1 150" armature="0.01" range="-180.0000 180.0000" damping="0" stiffness="0"/>
                        <geom type="capsule" contype="1" conaffinity="1" density="500" fromto="-0.0006 -0.0014 -0.0049 -0.0025 -0.0055 -0.0194" size="0.0085" name="R_Index2"/>
                        <body name="R_Index3" pos="-0.0031 -0.0068 -0.0243">
                          <joint name="R_Index3_x" type="hinge" pos="0 0 0" axis="1 0 0" user="100 10 1 150" armature="0.01" range="-180.0000 180.0000" damping="0" stiffness="0"/>
                          <joint name="R_Index3_y" type="hinge" pos="0 0 0" axis="0 1 0" user="100 10 1 150" armature="0.01" range="-180.0000 180.0000" damping="0" stiffness="0"/>
                          <joint name="R_Index3_z" type="hinge" pos="0 0 0" axis="0 0 1" user="100 10 1 150" armature="0.01" range="-180.0000 180.0000" damping="0" stiffness="0"/>
                          <geom type="capsule" contype="1" conaffinity="1" density="500" fromto="-0.0002 -0.0010 -0.0045 -0.0009 -0.0039 -0.0178" size="0.0078" name="R_Index3"/>
                        </body>
                      </body>
                    </body>
                    <body name="R_Middle1" pos="-0.0046 -0.1257 -0.0093">
                      <joint name="R_Middle1_x" type="hinge" pos="0 0 0" axis="1 0 0" user="100 10 1 150" armature="0.01" range="-180.0000 180.0000" damping="0" stiffness="0"/>
                      <joint name="R_Middle1_y" type="hinge" pos="0 0 0" axis="0 1 0" user="100 10 1 150" armature="0.01" range="-180.0000 180.0000" damping="0" stiffness="0"/>
                      <joint name="R_Middle1_z" type="hinge" pos="0 0 0" axis="0 0 1" user="100 10 1 150" armature="0.01" range="-180.0000 180.0000" damping="0" stiffness="0"/>
                      <geom type="capsule" contype="1" conaffinity="1" density="500" fromto="-0.0010 -0.0059 -0.0034 -0.0041 -0.0238 -0.0137" size="0.0109" name="R_Middle1"/>
                      <body name="R_Middle2" pos="-0.0051 -0.0297 -0.0171">
                        <joint name="R_Middle2_x" type="hinge" pos="0 0 0" axis="1 0 0" user="100 10 1 150" armature="0.01" range="-180.0000 180.0000" damping="0" stiffness="0"/>
                        <joint name="R_Middle2_y" type="hinge" pos="0 0 0" axis="0 1 0" user="100 10 1 150" armature="0.01" range="-180.0000 180.0000" damping="0" stiffness="0"/>
                        <joint name="R_Middle2_z" type="hinge" pos="0 0 0" axis="0 0 1" user="100 10 1 150" armature="0.01" range="-180.0000 180.0000" damping="0" stiffness="0"/>
                        <geom type="capsule" contype="1" conaffinity="1" density="500" fromto="-0.0004 -0.0010 -0.0052 -0.0017 -0.0040 -0.0209" size="0.0082" name="R_Middle2"/>
                        <body name="R_Middle3" pos="-0.0021 -0.005 -0.0262">
                          <joint name="R_Middle3_x" type="hinge" pos="0 0 0" axis="1 0 0" user="100 10 1 150" armature="0.01" range="-180.0000 180.0000" damping="0" stiffness="0"/>
                          <joint name="R_Middle3_y" type="hinge" pos="0 0 0" axis="0 1 0" user="100 10 1 150" armature="0.01" range="-180.0000 180.0000" damping="0" stiffness="0"/>
                          <joint name="R_Middle3_z" type="hinge" pos="0 0 0" axis="0 0 1" user="100 10 1 150" armature="0.01" range="-180.0000 180.0000" damping="0" stiffness="0"/>
                          <geom type="capsule" contype="1" conaffinity="1" density="500" fromto="-0.0000 -0.0006 -0.0048 -0.0001 -0.0024 -0.0193" size="0.0074" name="R_Middle3"/>
                        </body>
                      </body>
                    </body>
                    <body name="R_Pinky1" pos="-0.0538 -0.0957 -0.0193">
                      <joint name="R_Pinky1_x" type="hinge" pos="0 0 0" axis="1 0 0" user="100 10 1 150" armature="0.01" range="-180.0000 180.0000" damping="0" stiffness="0"/>
                      <joint name="R_Pinky1_y" type="hinge" pos="0 0 0" axis="0 1 0" user="100 10 1 150" armature="0.01" range="-180.0000 180.0000" damping="0" stiffness="0"/>
                      <joint name="R_Pinky1_z" type="hinge" pos="0 0 0" axis="0 0 1" user="100 10 1 150" armature="0.01" range="-180.0000 180.0000" damping="0" stiffness="0"/>
                      <geom type="capsule" contype="1" conaffinity="1" density="500" fromto="-0.0010 -0.0027 -0.0034 -0.0041 -0.0108 -0.0137" size="0.0081" name="R_Pinky1"/>
                      <body name="R_Pinky2" pos="-0.0051 -0.0136 -0.0171">
                        <joint name="R_Pinky2_x" type="hinge" pos="0 0 0" axis="1 0 0" user="100 10 1 150" armature="0.01" range="-180.0000 180.0000" damping="0" stiffness="0"/>
                        <joint name="R_Pinky2_y" type="hinge" pos="0 0 0" axis="0 1 0" user="100 10 1 150" armature="0.01" range="-180.0000 180.0000" damping="0" stiffness="0"/>
                        <joint name="R_Pinky2_z" type="hinge" pos="0 0 0" axis="0 0 1" user="100 10 1 150" armature="0.01" range="-180.0000 180.0000" damping="0" stiffness="0"/>
                        <geom type="capsule" contype="1" conaffinity="1" density="500" fromto="0.0002 -0.0008 -0.0042 0.0008 -0.0030 -0.0169" size="0.0072" name="R_Pinky2"/>
                        <body name="R_Pinky3" pos="0.0011 -0.0038 -0.0212">
                          <joint name="R_Pinky3_x" type="hinge" pos="0 0 0" axis="1 0 0" user="100 10 1 150" armature="0.01" range="-180.0000 180.0000" damping="0" stiffness="0"/>
                          <joint name="R_Pinky3_y" type="hinge" pos="0 0 0" axis="0 1 0" user="100 10 1 150" armature="0.01" range="-180.0000 180.0000" damping="0" stiffness="0"/>
                          <joint name="R_Pinky3_z" type="hinge" pos="0 0 0" axis="0 0 1" user="100 10 1 150" armature="0.01" range="-180.0000 180.0000" damping="0" stiffness="0"/>
                          <geom type="capsule" contype="1" conaffinity="1" density="500" fromto="0.0006 -0.0004 -0.0038 0.0024 -0.0014 -0.0153" size="0.0058" name="R_Pinky3"/>
                        </body>
                      </body>
                    </body>
                    <body name="R_Ring1" pos="-0.0334 -0.1115 -0.0125">
                      <joint name="R_Ring1_x" type="hinge" pos="0 0 0" axis="1 0 0" user="100 10 1 150" armature="0.01" range="-180.0000 180.0000" damping="0" stiffness="0"/>
                      <joint name="R_Ring1_y" type="hinge" pos="0 0 0" axis="0 1 0" user="100 10 1 150" armature="0.01" range="-180.0000 180.0000" damping="0" stiffness="0"/>
                      <joint name="R_Ring1_z" type="hinge" pos="0 0 0" axis="0 0 1" user="100 10 1 150" armature="0.01" range="-180.0000 180.0000" damping="0" stiffness="0"/>
                      <geom type="capsule" contype="1" conaffinity="1" density="500" fromto="-0.0002 -0.0053 -0.0037 -0.0010 -0.0212 -0.0149" size="0.0093" name="R_Ring1"/>
                      <body name="R_Ring2" pos="-0.0012 -0.0265 -0.0187">
                        <joint name="R_Ring2_x" type="hinge" pos="0 0 0" axis="1 0 0" user="100 10 1 150" armature="0.01" range="-180.0000 180.0000" damping="0" stiffness="0"/>
                        <joint name="R_Ring2_y" type="hinge" pos="0 0 0" axis="0 1 0" user="100 10 1 150" armature="0.01" range="-180.0000 180.0000" damping="0" stiffness="0"/>
                        <joint name="R_Ring2_z" type="hinge" pos="0 0 0" axis="0 0 1" user="100 10 1 150" armature="0.01" range="-180.0000 180.0000" damping="0" stiffness="0"/>
                        <geom type="capsule" contype="1" conaffinity="1" density="500" fromto="0.0004 -0.0008 -0.0052 0.0014 -0.0033 -0.0210" size="0.0084" name="R_Ring2"/>
                        <body name="R_Ring3" pos="0.0018 -0.0041 -0.0262">
                          <joint name="R_Ring3_x" type="hinge" pos="0 0 0" axis="1 0 0" user="100 10 1 150" armature="0.01" range="-180.0000 180.0000" damping="0" stiffness="0"/>
                          <joint name="R_Ring3_y" type="hinge" pos="0 0 0" axis="0 1 0" user="100 10 1 150" armature="0.01" range="-180.0000 180.0000" damping="0" stiffness="0"/>
                          <joint name="R_Ring3_z" type="hinge" pos="0 0 0" axis="0 0 1" user="100 10 1 150" armature="0.01" range="-180.0000 180.0000" damping="0" stiffness="0"/>
                          <geom type="capsule" contype="1" conaffinity="1" density="500" fromto="0.0008 -0.0004 -0.0048 0.0030 -0.0017 -0.0194" size="0.0069" name="R_Ring3"/>
                        </body>
                      </body>
                    </body>
                    <body name="R_Thumb1" pos="0.03 -0.0457 -0.0258">
                      <joint name="R_Thumb1_x" type="hinge" pos="0 0 0" axis="1 0 0" user="100 10 1 150" armature="0.01" range="-180.0000 180.0000" damping="0" stiffness="0"/>
                      <joint name="R_Thumb1_y" type="hinge" pos="0 0 0" axis="0 1 0" user="100 10 1 150" armature="0.01" range="-180.0000 180.0000" damping="0" stiffness="0"/>
                      <joint name="R_Thumb1_z" type="hinge" pos="0 0 0" axis="0 0 1" user="100 10 1 150" armature="0.01" range="-180.0000 180.0000" damping="0" stiffness="0"/>
                      <geom type="capsule" contype="1" conaffinity="1" density="500" fromto="0.0031 -0.0049 -0.0040 0.0122 -0.0197 -0.0160" size="0.0146" name="R_Thumb1"/>
                      <body name="R_Thumb2" pos="0.0153 -0.0246 -0.02">
                        <joint name="R_Thumb2_x" type="hinge" pos="0 0 0" axis="1 0 0" user="100 10 1 150" armature="0.01" range="-180.0000 180.0000" damping="0" stiffness="0"/>
                        <joint name="R_Thumb2_y" type="hinge" pos="0 0 0" axis="0 1 0" user="100 10 1 150" armature="0.01" range="-180.0000 180.0000" damping="0" stiffness="0"/>
                        <joint name="R_Thumb2_z" type="hinge" pos="0 0 0" axis="0 0 1" user="100 10 1 150" armature="0.01" range="-180.0000 180.0000" damping="0" stiffness="0"/>
                        <geom type="capsule" contype="1" conaffinity="1" density="500" fromto="0.0017 -0.0053 -0.0019 0.0067 -0.0212 -0.0077" size="0.0112" name="R_Thumb2"/>
                        <body name="R_Thumb3" pos="0.0084 -0.0265 -0.0096">
                          <joint name="R_Thumb3_x" type="hinge" pos="0 0 0" axis="1 0 0" user="100 10 1 150" armature="0.01" range="-180.0000 180.0000" damping="0" stiffness="0"/>
                          <joint name="R_Thumb3_y" type="hinge" pos="0 0 0" axis="0 1 0" user="100 10 1 150" armature="0.01" range="-180.0000 180.0000" damping="0" stiffness="0"/>
                          <joint name="R_Thumb3_z" type="hinge" pos="0 0 0" axis="0 0 1" user="100 10 1 150" armature="0.01" range="-180.0000 180.0000" damping="0" stiffness="0"/>
                          <geom type="capsule" contype="1" conaffinity="1" density="500" fromto="0.0021 -0.0049 -0.0015 0.0083 -0.0196 -0.0061" size="0.0105" name="R_Thumb3"/>
                        </body>
                      </body>
                    </body>
                  </body>
                </body>
              </body>
            </body>
          </body>
        </body>
      </body>
    </body>
  </worldbody>
  <actuator>
    <motor name="L_Hip_x" joint="L_Hip_x" gear="1"/>
    <motor name="L_Hip_y" joint="L_Hip_y" gear="1"/>
    <motor name="L_Hip_z" joint="L_Hip_z" gear="1"/>
    <motor name="L_Knee_x" joint="L_Knee_x" gear="1"/>
    <motor name="L_Knee_y" joint="L_Knee_y" gear="1"/>
    <motor name="L_Knee_z" joint="L_Knee_z" gear="1"/>
    <motor name="L_Ankle_x" joint="L_Ankle_x" gear="1"/>
    <motor name="L_Ankle_y" joint="L_Ankle_y" gear="1"/>
    <motor name="L_Ankle_z" joint="L_Ankle_z" gear="1"/>
    <motor name="L_Toe_x" joint="L_Toe_x" gear="1"/>
    <motor name="L_Toe_y" joint="L_Toe_y" gear="1"/>
    <motor name="L_Toe_z" joint="L_Toe_z" gear="1"/>
    <motor name="R_Hip_x" joint="R_Hip_x" gear="1"/>
    <motor name="R_Hip_y" joint="R_Hip_y" gear="1"/>
    <motor name="R_Hip_z" joint="R_Hip_z" gear="1"/>
    <motor name="R_Knee_x" joint="R_Knee_x" gear="1"/>
    <motor name="R_Knee_y" joint="R_Knee_y" gear="1"/>
    <motor name="R_Knee_z" joint="R_Knee_z" gear="1"/>
    <motor name="R_Ankle_x" joint="R_Ankle_x" gear="1"/>
    <motor name="R_Ankle_y" joint="R_Ankle_y" gear="1"/>
    <motor name="R_Ankle_z" joint="R_Ankle_z" gear="1"/>
    <motor name="R_Toe_x" joint="R_Toe_x" gear="1"/>
    <motor name="R_Toe_y" joint="R_Toe_y" gear="1"/>
    <motor name="R_Toe_z" joint="R_Toe_z" gear="1"/>
    <motor name="Torso_x" joint="Torso_x" gear="1"/>
    <motor name="Torso_y" joint="Torso_y" gear="1"/>
    <motor name="Torso_z" joint="Torso_z" gear="1"/>
    <motor name="Spine_x" joint="Spine_x" gear="1"/>
    <motor name="Spine_y" joint="Spine_y" gear="1"/>
    <motor name="Spine_z" joint="Spine_z" gear="1"/>
    <motor name="Chest_x" joint="Chest_x" gear="1"/>
    <motor name="Chest_y" joint="Chest_y" gear="1"/>
    <motor name="Chest_z" joint="Chest_z" gear="1"/>
    <motor name="Neck_x" joint="Neck_x" gear="1"/>
    <motor name="Neck_y" joint="Neck_y" gear="1"/>
    <motor name="Neck_z" joint="Neck_z" gear="1"/>
    <motor name="Head_x" joint="Head_x" gear="1"/>
    <motor name="Head_y" joint="Head_y" gear="1"/>
    <motor name="Head_z" joint="Head_z" gear="1"/>
    <motor name="L_Thorax_x" joint="L_Thorax_x" gear="1"/>
    <motor name="L_Thorax_y" joint="L_Thorax_y" gear="1"/>
    <motor name="L_Thorax_z" joint="L_Thorax_z" gear="1"/>
    <motor name="L_Shoulder_x" joint="L_Shoulder_x" gear="1"/>
    <motor name="L_Shoulder_y" joint="L_Shoulder_y" gear="1"/>
    <motor name="L_Shoulder_z" joint="L_Shoulder_z" gear="1"/>
    <motor name="L_Elbow_x" joint="L_Elbow_x" gear="1"/>
    <motor name="L_Elbow_y" joint="L_Elbow_y" gear="1"/>
    <motor name="L_Elbow_z" joint="L_Elbow_z" gear="1"/>
    <motor name="L_Wrist_x" joint="L_Wrist_x" gear="1"/>
    <motor name="L_Wrist_y" joint="L_Wrist_y" gear="1"/>
    <motor name="L_Wrist_z" joint="L_Wrist_z" gear="1"/>
    <motor name="L_Index1_x" joint="L_Index1_x" gear="1"/>
    <motor name="L_Index1_y" joint="L_Index1_y" gear="1"/>
    <motor name="L_Index1_z" joint="L_Index1_z" gear="1"/>
    <motor name="L_Index2_x" joint="L_Index2_x" gear="1"/>
    <motor name="L_Index2_y" joint="L_Index2_y" gear="1"/>
    <motor name="L_Index2_z" joint="L_Index2_z" gear="1"/>
    <motor name="L_Index3_x" joint="L_Index3_x" gear="1"/>
    <motor name="L_Index3_y" joint="L_Index3_y" gear="1"/>
    <motor name="L_Index3_z" joint="L_Index3_z" gear="1"/>
    <motor name="L_Middle1_x" joint="L_Middle1_x" gear="1"/>
    <motor name="L_Middle1_y" joint="L_Middle1_y" gear="1"/>
    <motor name="L_Middle1_z" joint="L_Middle1_z" gear="1"/>
    <motor name="L_Middle2_x" joint="L_Middle2_x" gear="1"/>
    <motor name="L_Middle2_y" joint="L_Middle2_y" gear="1"/>
    <motor name="L_Middle2_z" joint="L_Middle2_z" gear="1"/>
    <motor name="L_Middle3_x" joint="L_Middle3_x" gear="1"/>
    <motor name="L_Middle3_y" joint="L_Middle3_y" gear="1"/>
    <motor name="L_Middle3_z" joint="L_Middle3_z" gear="1"/>
    <motor name="L_Pinky1_x" joint="L_Pinky1_x" gear="1"/>
    <motor name="L_Pinky1_y" joint="L_Pinky1_y" gear="1"/>
    <motor name="L_Pinky1_z" joint="L_Pinky1_z" gear="1"/>
    <motor name="L_Pinky2_x" joint="L_Pinky2_x" gear="1"/>
    <motor name="L_Pinky2_y" joint="L_Pinky2_y" gear="1"/>
    <motor name="L_Pinky2_z" joint="L_Pinky2_z" gear="1"/>
    <motor name="L_Pinky3_x" joint="L_Pinky3_x" gear="1"/>
    <motor name="L_Pinky3_y" joint="L_Pinky3_y" gear="1"/>
    <motor name="L_Pinky3_z" joint="L_Pinky3_z" gear="1"/>
    <motor name="L_Ring1_x" joint="L_Ring1_x" gear="1"/>
    <motor name="L_Ring1_y" joint="L_Ring1_y" gear="1"/>
    <motor name="L_Ring1_z" joint="L_Ring1_z" gear="1"/>
    <motor name="L_Ring2_x" joint="L_Ring2_x" gear="1"/>
    <motor name="L_Ring2_y" joint="L_Ring2_y" gear="1"/>
    <motor name="L_Ring2_z" joint="L_Ring2_z" gear="1"/>
    <motor name="L_Ring3_x" joint="L_Ring3_x" gear="1"/>
    <motor name="L_Ring3_y" joint="L_Ring3_y" gear="1"/>
    <motor name="L_Ring3_z" joint="L_Ring3_z" gear="1"/>
    <motor name="L_Thumb1_x" joint="L_Thumb1_x" gear="1"/>
    <motor name="L_Thumb1_y" joint="L_Thumb1_y" gear="1"/>
    <motor name="L_Thumb1_z" joint="L_Thumb1_z" gear="1"/>
    <motor name="L_Thumb2_x" joint="L_Thumb2_x" gear="1"/>
    <motor name="L_Thumb2_y" joint="L_Thumb2_y" gear="1"/>
    <motor name="L_Thumb2_z" joint="L_Thumb2_z" gear="1"/>
    <motor name="L_Thumb3_x" joint="L_Thumb3_x" gear="1"/>
    <motor name="L_Thumb3_y" joint="L_Thumb3_y" gear="1"/>
    <motor name="L_Thumb3_z" joint="L_Thumb3_z" gear="1"/>
    <motor name="R_Thorax_x" joint="R_Thorax_x" gear="1"/>
    <motor name="R_Thorax_y" joint="R_Thorax_y" gear="1"/>
    <motor name="R_Thorax_z" joint="R_Thorax_z" gear="1"/>
    <motor name="R_Shoulder_x" joint="R_Shoulder_x" gear="1"/>
    <motor name="R_Shoulder_y" joint="R_Shoulder_y" gear="1"/>
    <motor name="R_Shoulder_z" joint="R_Shoulder_z" gear="1"/>
    <motor name="R_Elbow_x" joint="R_Elbow_x" gear="1"/>
    <motor name="R_Elbow_y" joint="R_Elbow_y" gear="1"/>
    <motor name="R_Elbow_z" joint="R_Elbow_z" gear="1"/>
    <motor name="R_Wrist_x" joint="R_Wrist_x" gear="1"/>
    <motor name="R_Wrist_y" joint="R_Wrist_y" gear="1"/>
    <motor name="R_Wrist_z" joint="R_Wrist_z" gear="1"/>
    <motor name="R_Index1_x" joint="R_Index1_x" gear="1"/>
    <motor name="R_Index1_y" joint="R_Index1_y" gear="1"/>
    <motor name="R_Index1_z" joint="R_Index1_z" gear="1"/>
    <motor name="R_Index2_x" joint="R_Index2_x" gear="1"/>
    <motor name="R_Index2_y" joint="R_Index2_y" gear="1"/>
    <motor name="R_Index2_z" joint="R_Index2_z" gear="1"/>
    <motor name="R_Index3_x" joint="R_Index3_x" gear="1"/>
    <motor name="R_Index3_y" joint="R_Index3_y" gear="1"/>
    <motor name="R_Index3_z" joint="R_Index3_z" gear="1"/>
    <motor name="R_Middle1_x" joint="R_Middle1_x" gear="1"/>
    <motor name="R_Middle1_y" joint="R_Middle1_y" gear="1"/>
    <motor name="R_Middle1_z" joint="R_Middle1_z" gear="1"/>
    <motor name="R_Middle2_x" joint="R_Middle2_x" gear="1"/>
    <motor name="R_Middle2_y" joint="R_Middle2_y" gear="1"/>
    <motor name="R_Middle2_z" joint="R_Middle2_z" gear="1"/>
    <motor name="R_Middle3_x" joint="R_Middle3_x" gear="1"/>
    <motor name="R_Middle3_y" joint="R_Middle3_y" gear="1"/>
    <motor name="R_Middle3_z" joint="R_Middle3_z" gear="1"/>
    <motor name="R_Pinky1_x" joint="R_Pinky1_x" gear="1"/>
    <motor name="R_Pinky1_y" joint="R_Pinky1_y" gear="1"/>
    <motor name="R_Pinky1_z" joint="R_Pinky1_z" gear="1"/>
    <motor name="R_Pinky2_x" joint="R_Pinky2_x" gear="1"/>
    <motor name="R_Pinky2_y" joint="R_Pinky2_y" gear="1"/>
    <motor name="R_Pinky2_z" joint="R_Pinky2_z" gear="1"/>
    <motor name="R_Pinky3_x" joint="R_Pinky3_x" gear="1"/>
    <motor name="R_Pinky3_y" joint="R_Pinky3_y" gear="1"/>
    <motor name="R_Pinky3_z" joint="R_Pinky3_z" gear="1"/>
    <motor name="R_Ring1_x" joint="R_Ring1_x" gear="1"/>
    <motor name="R_Ring1_y" joint="R_Ring1_y" gear="1"/>
    <motor name="R_Ring1_z" joint="R_Ring1_z" gear="1"/>
    <motor name="R_Ring2_x" joint="R_Ring2_x" gear="1"/>
    <motor name="R_Ring2_y" joint="R_Ring2_y" gear="1"/>
    <motor name="R_Ring2_z" joint="R_Ring2_z" gear="1"/>
    <motor name="R_Ring3_x" joint="R_Ring3_x" gear="1"/>
    <motor name="R_Ring3_y" joint="R_Ring3_y" gear="1"/>
    <motor name="R_Ring3_z" joint="R_Ring3_z" gear="1"/>
    <motor name="R_Thumb1_x" joint="R_Thumb1_x" gear="1"/>
    <motor name="R_Thumb1_y" joint="R_Thumb1_y" gear="1"/>
    <motor name="R_Thumb1_z" joint="R_Thumb1_z" gear="1"/>
    <motor name="R_Thumb2_x" joint="R_Thumb2_x" gear="1"/>
    <motor name="R_Thumb2_y" joint="R_Thumb2_y" gear="1"/>
    <motor name="R_Thumb2_z" joint="R_Thumb2_z" gear="1"/>
    <motor name="R_Thumb3_x" joint="R_Thumb3_x" gear="1"/>
    <motor name="R_Thumb3_y" joint="R_Thumb3_y" gear="1"/>
    <motor name="R_Thumb3_z" joint="R_Thumb3_z" gear="1"/>
  </actuator>
  <contact>
    <exclude body1="Torso" body2="Chest"/>
    <exclude body1="Head" body2="Chest"/>
    <exclude body1="R_Knee" body2="R_Toe"/>
    <exclude body1="R_Knee" body2="L_Ankle"/>
    <exclude body1="R_Knee" body2="L_Toe"/>
    <exclude body1="L_Knee" body2="L_Toe"/>
    <exclude body1="L_Knee" body2="R_Ankle"/>
    <exclude body1="L_Knee" body2="R_Toe"/>
    <exclude body1="L_Shoulder" body2="Chest"/>
    <exclude body1="R_Shoulder" body2="Chest"/>
  </contact>
  <sensor/>
  <size njmax="700" nconmax="700"/>
</mujoco>
